Workbook

Sheet 说明
A1: CreditMetrics 单因子 Excel 模板
A3: 用途 | B3: 基于评级迁移、信用利差与单系统因子模拟，实现 CreditMetrics 风格的组合信用风险测算模板。
A4: 建议流程 | B4: 1. 调整参数 2. 录入迁移矩阵与利差 3. 维护组合输入 4. 查看状态价值 5. 在结果页读取 VaR / ES
A5: 关键假设 | B5: 一年持有期、年度票息、违约价值 = 面值 × 回收率、相关性通过系统因子权重近似。
A6: 扩展方式 | B6: 若需更多债项，复制“组合输入”和“状态价值”行，以及“模拟”中每个债项对应的 5 列块。
A8: 工作表
A9: 参数 | B9: 持有期、置信度、模拟次数、无风险利率
A10: 评级迁移 | B10: 评级迁移矩阵与累计概率
A11: 利差假设 | B11: 远期估值所需的评级利差
A12: 组合输入 | B12: 债项面值、票息、期限、回收率、系统因子权重
A13: 状态价值 | B13: 每个债项在不同迁移终点下的价值与解析统计
A14: 模拟 | B14: 蒙特卡洛模拟场景、迁移结果与组合损失
A15: 结果 | B15: 组合层面的 EL、UL、VaR、ES 与模拟/解析校验

Sheet 参数
A1: 参数 | B1: 值
A2: 持有期(年) | B2: 1
A3: 置信度 | B3: 0.99
A4: 模拟次数(≤500) | B4: 200
A5: 无风险利率 | B5: 0.03
A6: 损失分位数说明 | B6: 结果页 VaR/ES 基于模拟损失分布

Sheet 评级迁移
A1: 当前评级 | B1: AAA | C1: AA | D1: A | E1: BBB | F1: BB | G1: B | H1: CCC | I1: D | K1: 累计AAA | L1: 累计AA | M1: 累计A | N1: 累计BBB | O1: 累计BB | P1: 累计B | Q1: 累计CCC | R1: 累计D | S1: 行和
A2: AAA | B2: 0.9 | C2: 0.085 | D2: 0.01 | E2: 0.003 | F2: 0.001 | G2: 0.0005 | H2: 0 | I2: 0.0005 | K2: =SUM($B2:B2) | L2: =SUM($B2:C2) | M2: =SUM($B2:D2) | N2: =SUM($B2:E2) | O2: =SUM($B2:F2) | P2: =SUM($B2:G2) | Q2: =SUM($B2:H2) | R2: =SUM($B2:I2) | S2: =SUM($B2:$I2)
A3: AA | B3: 0.02 | C3: 0.88 | D3: 0.07 | E3: 0.02 | F3: 0.005 | G3: 0.003 | H3: 0.001 | I3: 0.001 | K3: =SUM($B3:B3) | L3: =SUM($B3:C3) | M3: =SUM($B3:D3) | N3: =SUM($B3:E3) | O3: =SUM($B3:F3) | P3: =SUM($B3:G3) | Q3: =SUM($B3:H3) | R3: =SUM($B3:I3) | S3: =SUM($B3:$I3)
A4: A | B4: 0.005 | C4: 0.03 | D4: 0.87 | E4: 0.07 | F4: 0.015 | G4: 0.005 | H4: 0.003 | I4: 0.002 | K4: =SUM($B4:B4) | L4: =SUM($B4:C4) | M4: =SUM($B4:D4) | N4: =SUM($B4:E4) | O4: =SUM($B4:F4) | P4: =SUM($B4:G4) | Q4: =SUM($B4:H4) | R4: =SUM($B4:I4) | S4: =SUM($B4:$I4)
A5: BBB | B5: 0.001 | C5: 0.01 | D5: 0.06 | E5: 0.83 | F5: 0.06 | G5: 0.02 | H5: 0.01 | I5: 0.009 | K5: =SUM($B5:B5) | L5: =SUM($B5:C5) | M5: =SUM($B5:D5) | N5: =SUM($B5:E5) | O5: =SUM($B5:F5) | P5: =SUM($B5:G5) | Q5: =SUM($B5:H5) | R5: =SUM($B5:I5) | S5: =SUM($B5:$I5)
A6: BB | B6: 0 | C6: 0.003 | D6: 0.015 | E6: 0.07 | F6: 0.79 | G6: 0.08 | H6: 0.02 | I6: 0.022 | K6: =SUM($B6:B6) | L6: =SUM($B6:C6) | M6: =SUM($B6:D6) | N6: =SUM($B6:E6) | O6: =SUM($B6:F6) | P6: =SUM($B6:G6) | Q6: =SUM($B6:H6) | R6: =SUM($B6:I6) | S6: =SUM($B6:$I6)
A7: B | B7: 0 | C7: 0.001 | D7: 0.005 | E7: 0.02 | F7: 0.07 | G7: 0.78 | H7: 0.06 | I7: 0.064 | K7: =SUM($B7:B7) | L7: =SUM($B7:C7) | M7: =SUM($B7:D7) | N7: =SUM($B7:E7) | O7: =SUM($B7:F7) | P7: =SUM($B7:G7) | Q7: =SUM($B7:H7) | R7: =SUM($B7:I7) | S7: =SUM($B7:$I7)
A8: CCC | B8: 0 | C8: 0 | D8: 0.002 | E8: 0.008 | F8: 0.03 | G8: 0.12 | H8: 0.62 | I8: 0.22 | K8: =SUM($B8:B8) | L8: =SUM($B8:C8) | M8: =SUM($B8:D8) | N8: =SUM($B8:E8) | O8: =SUM($B8:F8) | P8: =SUM($B8:G8) | Q8: =SUM($B8:H8) | R8: =SUM($B8:I8) | S8: =SUM($B8:$I8)
A9: D | B9: 0 | C9: 0 | D9: 0 | E9: 0 | F9: 0 | G9: 0 | H9: 0 | I9: 1 | K9: =SUM($B9:B9) | L9: =SUM($B9:C9) | M9: =SUM($B9:D9) | N9: =SUM($B9:E9) | O9: =SUM($B9:F9) | P9: =SUM($B9:G9) | Q9: =SUM($B9:H9) | R9: =SUM($B9:I9) | S9: =SUM($B9:$I9)

Sheet 利差假设
A1: 评级 | B1: 信用利差 | C1: 贴现率(=rf+spread)
A2: AAA | B2: 0.005 | C2: ='参数'!$B$5+B2
A3: AA | B3: 0.008 | C3: ='参数'!$B$5+B3
A4: A | B4: 0.012 | C4: ='参数'!$B$5+B4
A5: BBB | B5: 0.02 | C5: ='参数'!$B$5+B5
A6: BB | B6: 0.04 | C6: ='参数'!$B$5+B6
A7: B | B7: 0.06 | C7: ='参数'!$B$5+B7
A8: CCC | B8: 0.1 | C8: ='参数'!$B$5+B8
A9: D | B9: 0 | C9: ='参数'!$B$5+B9

Sheet 组合输入
A1: 序号 | B1: 债项名称 | C1: 当前评级 | D1: 面值 | E1: 票息率 | F1: 剩余期限(年) | G1: 回收率 | H1: 系统因子权重 | I1: 当前利差 | J1: 当前价值 | K1: 累计AAA | L1: 累计AA | M1: 累计A | N1: 累计BBB | O1: 累计BB | P1: 累计B | Q1: 累计CCC | R1: 累计D
A2: 1 | B2: AutoSupplier | C2: BBB | D2: 10000000 | E2: 0.055 | F2: 5 | G2: 0.4 | H2: 0.45 | I2: =IF($C2="","",INDEX('利差假设'!$B$2:$B$9,MATCH($C2,'利差假设'!$A$2:$A$9,0))) | J2: =IF($C2="","",IF($C2="D",$D2*$G2,IF($F2<=1,$D2*(1+$E2),$D2*$E2+IF('参数'!$B$5+$I2=0,$D2+$D2*$E2*($F2-1),$D2*$E2*(1-(1+'参数'!$B$5+$I2)^-($F2-1))/('参数'!$B$5+$I2)+$D2*(1+'参数'!$B$5+$I2)^-($F2-1))))) | K2: =IF($C2="","",INDEX('评级迁移'!$K$2:$K$9,MATCH($C2,'评级迁移'!$A$2:$A$9,0))) | L2: =IF($C2="","",INDEX('评级迁移'!$L$2:$L$9,MATCH($C2,'评级迁移'!$A$2:$A$9,0))) | M2: =IF($C2="","",INDEX('评级迁移'!$M$2:$M$9,MATCH($C2,'评级迁移'!$A$2:$A$9,0))) | N2: =IF($C2="","",INDEX('评级迁移'!$N$2:$N$9,MATCH($C2,'评级迁移'!$A$2:$A$9,0))) | O2: =IF($C2="","",INDEX('评级迁移'!$O$2:$O$9,MATCH($C2,'评级迁移'!$A$2:$A$9,0))) | P2: =IF($C2="","",INDEX('评级迁移'!$P$2:$P$9,MATCH($C2,'评级迁移'!$A$2:$A$9,0))) | Q2: =IF($C2="","",INDEX('评级迁移'!$Q$2:$Q$9,MATCH($C2,'评级迁移'!$A$2:$A$9,0))) | R2: =IF($C2="","",INDEX('评级迁移'!$R$2:$R$9,MATCH($C2,'评级迁移'!$A$2:$A$9,0)))
A3: 2 | B3: PowerUtility | C3: A | D3: 12000000 | E3: 0.042 | F3: 4 | G3: 0.38 | H3: 0.35 | I3: =IF($C3="","",INDEX('利差假设'!$B$2:$B$9,MATCH($C3,'利差假设'!$A$2:$A$9,0))) | J3: =IF($C3="","",IF($C3="D",$D3*$G3,IF($F3<=1,$D3*(1+$E3),$D3*$E3+IF('参数'!$B$5+$I3=0,$D3+$D3*$E3*($F3-1),$D3*$E3*(1-(1+'参数'!$B$5+$I3)^-($F3-1))/('参数'!$B$5+$I3)+$D3*(1+'参数'!$B$5+$I3)^-($F3-1))))) | K3: =IF($C3="","",INDEX('评级迁移'!$K$2:$K$9,MATCH($C3,'评级迁移'!$A$2:$A$9,0))) | L3: =IF($C3="","",INDEX('评级迁移'!$L$2:$L$9,MATCH($C3,'评级迁移'!$A$2:$A$9,0))) | M3: =IF($C3="","",INDEX('评级迁移'!$M$2:$M$9,MATCH($C3,'评级迁移'!$A$2:$A$9,0))) | N3: =IF($C3="","",INDEX('评级迁移'!$N$2:$N$9,MATCH($C3,'评级迁移'!$A$2:$A$9,0))) | O3: =IF($C3="","",INDEX('评级迁移'!$O$2:$O$9,MATCH($C3,'评级迁移'!$A$2:$A$9,0))) | P3: =IF($C3="","",INDEX('评级迁移'!$P$2:$P$9,MATCH($C3,'评级迁移'!$A$2:$A$9,0))) | Q3: =IF($C3="","",INDEX('评级迁移'!$Q$2:$Q$9,MATCH($C3,'评级迁移'!$A$2:$A$9,0))) | R3: =IF($C3="","",INDEX('评级迁移'!$R$2:$R$9,MATCH($C3,'评级迁移'!$A$2:$A$9,0)))
A4: 3 | B4: RetailCo | C4: BB | D4: 8000000 | E4: 0.068 | F4: 3 | G4: 0.35 | H4: 0.5 | I4: =IF($C4="","",INDEX('利差假设'!$B$2:$B$9,MATCH($C4,'利差假设'!$A$2:$A$9,0))) | J4: =IF($C4="","",IF($C4="D",$D4*$G4,IF($F4<=1,$D4*(1+$E4),$D4*$E4+IF('参数'!$B$5+$I4=0,$D4+$D4*$E4*($F4-1),$D4*$E4*(1-(1+'参数'!$B$5+$I4)^-($F4-1))/('参数'!$B$5+$I4)+$D4*(1+'参数'!$B$5+$I4)^-($F4-1))))) | K4: =IF($C4="","",INDEX('评级迁移'!$K$2:$K$9,MATCH($C4,'评级迁移'!$A$2:$A$9,0))) | L4: =IF($C4="","",INDEX('评级迁移'!$L$2:$L$9,MATCH($C4,'评级迁移'!$A$2:$A$9,0))) | M4: =IF($C4="","",INDEX('评级迁移'!$M$2:$M$9,MATCH($C4,'评级迁移'!$A$2:$A$9,0))) | N4: =IF($C4="","",INDEX('评级迁移'!$N$2:$N$9,MATCH($C4,'评级迁移'!$A$2:$A$9,0))) | O4: =IF($C4="","",INDEX('评级迁移'!$O$2:$O$9,MATCH($C4,'评级迁移'!$A$2:$A$9,0))) | P4: =IF($C4="","",INDEX('评级迁移'!$P$2:$P$9,MATCH($C4,'评级迁移'!$A$2:$A$9,0))) | Q4: =IF($C4="","",INDEX('评级迁移'!$Q$2:$Q$9,MATCH($C4,'评级迁移'!$A$2:$A$9,0))) | R4: =IF($C4="","",INDEX('评级迁移'!$R$2:$R$9,MATCH($C4,'评级迁移'!$A$2:$A$9,0)))
A5: 4 | B5: TelecomInfra | C5: AA | D5: 15000000 | E5: 0.039 | F5: 6 | G5: 0.45 | H5: 0.3 | I5: =IF($C5="","",INDEX('利差假设'!$B$2:$B$9,MATCH($C5,'利差假设'!$A$2:$A$9,0))) | J5: =IF($C5="","",IF($C5="D",$D5*$G5,IF($F5<=1,$D5*(1+$E5),$D5*$E5+IF('参数'!$B$5+$I5=0,$D5+$D5*$E5*($F5-1),$D5*$E5*(1-(1+'参数'!$B$5+$I5)^-($F5-1))/('参数'!$B$5+$I5)+$D5*(1+'参数'!$B$5+$I5)^-($F5-1))))) | K5: =IF($C5="","",INDEX('评级迁移'!$K$2:$K$9,MATCH($C5,'评级迁移'!$A$2:$A$9,0))) | L5: =IF($C5="","",INDEX('评级迁移'!$L$2:$L$9,MATCH($C5,'评级迁移'!$A$2:$A$9,0))) | M5: =IF($C5="","",INDEX('评级迁移'!$M$2:$M$9,MATCH($C5,'评级迁移'!$A$2:$A$9,0))) | N5: =IF($C5="","",INDEX('评级迁移'!$N$2:$N$9,MATCH($C5,'评级迁移'!$A$2:$A$9,0))) | O5: =IF($C5="","",INDEX('评级迁移'!$O$2:$O$9,MATCH($C5,'评级迁移'!$A$2:$A$9,0))) | P5: =IF($C5="","",INDEX('评级迁移'!$P$2:$P$9,MATCH($C5,'评级迁移'!$A$2:$A$9,0))) | Q5: =IF($C5="","",INDEX('评级迁移'!$Q$2:$Q$9,MATCH($C5,'评级迁移'!$A$2:$A$9,0))) | R5: =IF($C5="","",INDEX('评级迁移'!$R$2:$R$9,MATCH($C5,'评级迁移'!$A$2:$A$9,0)))
A6: 5 | B6: PropertyDev | C6: B | D6: 6000000 | E6: 0.085 | F6: 2 | G6: 0.25 | H6: 0.55 | I6: =IF($C6="","",INDEX('利差假设'!$B$2:$B$9,MATCH($C6,'利差假设'!$A$2:$A$9,0))) | J6: =IF($C6="","",IF($C6="D",$D6*$G6,IF($F6<=1,$D6*(1+$E6),$D6*$E6+IF('参数'!$B$5+$I6=0,$D6+$D6*$E6*($F6-1),$D6*$E6*(1-(1+'参数'!$B$5+$I6)^-($F6-1))/('参数'!$B$5+$I6)+$D6*(1+'参数'!$B$5+$I6)^-($F6-1))))) | K6: =IF($C6="","",INDEX('评级迁移'!$K$2:$K$9,MATCH($C6,'评级迁移'!$A$2:$A$9,0))) | L6: =IF($C6="","",INDEX('评级迁移'!$L$2:$L$9,MATCH($C6,'评级迁移'!$A$2:$A$9,0))) | M6: =IF($C6="","",INDEX('评级迁移'!$M$2:$M$9,MATCH($C6,'评级迁移'!$A$2:$A$9,0))) | N6: =IF($C6="","",INDEX('评级迁移'!$N$2:$N$9,MATCH($C6,'评级迁移'!$A$2:$A$9,0))) | O6: =IF($C6="","",INDEX('评级迁移'!$O$2:$O$9,MATCH($C6,'评级迁移'!$A$2:$A$9,0))) | P6: =IF($C6="","",INDEX('评级迁移'!$P$2:$P$9,MATCH($C6,'评级迁移'!$A$2:$A$9,0))) | Q6: =IF($C6="","",INDEX('评级迁移'!$Q$2:$Q$9,MATCH($C6,'评级迁移'!$A$2:$A$9,0))) | R6: =IF($C6="","",INDEX('评级迁移'!$R$2:$R$9,MATCH($C6,'评级迁移'!$A$2:$A$9,0)))
A7: 6 | I7: =IF($C7="","",INDEX('利差假设'!$B$2:$B$9,MATCH($C7,'利差假设'!$A$2:$A$9,0))) | J7: =IF($C7="","",IF($C7="D",$D7*$G7,IF($F7<=1,$D7*(1+$E7),$D7*$E7+IF('参数'!$B$5+$I7=0,$D7+$D7*$E7*($F7-1),$D7*$E7*(1-(1+'参数'!$B$5+$I7)^-($F7-1))/('参数'!$B$5+$I7)+$D7*(1+'参数'!$B$5+$I7)^-($F7-1))))) | K7: =IF($C7="","",INDEX('评级迁移'!$K$2:$K$9,MATCH($C7,'评级迁移'!$A$2:$A$9,0))) | L7: =IF($C7="","",INDEX('评级迁移'!$L$2:$L$9,MATCH($C7,'评级迁移'!$A$2:$A$9,0))) | M7: =IF($C7="","",INDEX('评级迁移'!$M$2:$M$9,MATCH($C7,'评级迁移'!$A$2:$A$9,0))) | N7: =IF($C7="","",INDEX('评级迁移'!$N$2:$N$9,MATCH($C7,'评级迁移'!$A$2:$A$9,0))) | O7: =IF($C7="","",INDEX('评级迁移'!$O$2:$O$9,MATCH($C7,'评级迁移'!$A$2:$A$9,0))) | P7: =IF($C7="","",INDEX('评级迁移'!$P$2:$P$9,MATCH($C7,'评级迁移'!$A$2:$A$9,0))) | Q7: =IF($C7="","",INDEX('评级迁移'!$Q$2:$Q$9,MATCH($C7,'评级迁移'!$A$2:$A$9,0))) | R7: =IF($C7="","",INDEX('评级迁移'!$R$2:$R$9,MATCH($C7,'评级迁移'!$A$2:$A$9,0)))
A8: 7 | I8: =IF($C8="","",INDEX('利差假设'!$B$2:$B$9,MATCH($C8,'利差假设'!$A$2:$A$9,0))) | J8: =IF($C8="","",IF($C8="D",$D8*$G8,IF($F8<=1,$D8*(1+$E8),$D8*$E8+IF('参数'!$B$5+$I8=0,$D8+$D8*$E8*($F8-1),$D8*$E8*(1-(1+'参数'!$B$5+$I8)^-($F8-1))/('参数'!$B$5+$I8)+$D8*(1+'参数'!$B$5+$I8)^-($F8-1))))) | K8: =IF($C8="","",INDEX('评级迁移'!$K$2:$K$9,MATCH($C8,'评级迁移'!$A$2:$A$9,0))) | L8: =IF($C8="","",INDEX('评级迁移'!$L$2:$L$9,MATCH($C8,'评级迁移'!$A$2:$A$9,0))) | M8: =IF($C8="","",INDEX('评级迁移'!$M$2:$M$9,MATCH($C8,'评级迁移'!$A$2:$A$9,0))) | N8: =IF($C8="","",INDEX('评级迁移'!$N$2:$N$9,MATCH($C8,'评级迁移'!$A$2:$A$9,0))) | O8: =IF($C8="","",INDEX('评级迁移'!$O$2:$O$9,MATCH($C8,'评级迁移'!$A$2:$A$9,0))) | P8: =IF($C8="","",INDEX('评级迁移'!$P$2:$P$9,MATCH($C8,'评级迁移'!$A$2:$A$9,0))) | Q8: =IF($C8="","",INDEX('评级迁移'!$Q$2:$Q$9,MATCH($C8,'评级迁移'!$A$2:$A$9,0))) | R8: =IF($C8="","",INDEX('评级迁移'!$R$2:$R$9,MATCH($C8,'评级迁移'!$A$2:$A$9,0)))
A9: 8 | I9: =IF($C9="","",INDEX('利差假设'!$B$2:$B$9,MATCH($C9,'利差假设'!$A$2:$A$9,0))) | J9: =IF($C9="","",IF($C9="D",$D9*$G9,IF($F9<=1,$D9*(1+$E9),$D9*$E9+IF('参数'!$B$5+$I9=0,$D9+$D9*$E9*($F9-1),$D9*$E9*(1-(1+'参数'!$B$5+$I9)^-($F9-1))/('参数'!$B$5+$I9)+$D9*(1+'参数'!$B$5+$I9)^-($F9-1))))) | K9: =IF($C9="","",INDEX('评级迁移'!$K$2:$K$9,MATCH($C9,'评级迁移'!$A$2:$A$9,0))) | L9: =IF($C9="","",INDEX('评级迁移'!$L$2:$L$9,MATCH($C9,'评级迁移'!$A$2:$A$9,0))) | M9: =IF($C9="","",INDEX('评级迁移'!$M$2:$M$9,MATCH($C9,'评级迁移'!$A$2:$A$9,0))) | N9: =IF($C9="","",INDEX('评级迁移'!$N$2:$N$9,MATCH($C9,'评级迁移'!$A$2:$A$9,0))) | O9: =IF($C9="","",INDEX('评级迁移'!$O$2:$O$9,MATCH($C9,'评级迁移'!$A$2:$A$9,0))) | P9: =IF($C9="","",INDEX('评级迁移'!$P$2:$P$9,MATCH($C9,'评级迁移'!$A$2:$A$9,0))) | Q9: =IF($C9="","",INDEX('评级迁移'!$Q$2:$Q$9,MATCH($C9,'评级迁移'!$A$2:$A$9,0))) | R9: =IF($C9="","",INDEX('评级迁移'!$R$2:$R$9,MATCH($C9,'评级迁移'!$A$2:$A$9,0)))
A10: 9 | I10: =IF($C10="","",INDEX('利差假设'!$B$2:$B$9,MATCH($C10,'利差假设'!$A$2:$A$9,0))) | J10: =IF($C10="","",IF($C10="D",$D10*$G10,IF($F10<=1,$D10*(1+$E10),$D10*$E10+IF('参数'!$B$5+$I10=0,$D10+$D10*$E10*($F10-1),$D10*$E10*(1-(1+'参数'!$B$5+$I10)^-($F10-1))/('参数'!$B$5+$I10)+$D10*(1+'参数'!$B$5+$I10)^-($F10-1))))) | K10: =IF($C10="","",INDEX('评级迁移'!$K$2:$K$9,MATCH($C10,'评级迁移'!$A$2:$A$9,0))) | L10: =IF($C10="","",INDEX('评级迁移'!$L$2:$L$9,MATCH($C10,'评级迁移'!$A$2:$A$9,0))) | M10: =IF($C10="","",INDEX('评级迁移'!$M$2:$M$9,MATCH($C10,'评级迁移'!$A$2:$A$9,0))) | N10: =IF($C10="","",INDEX('评级迁移'!$N$2:$N$9,MATCH($C10,'评级迁移'!$A$2:$A$9,0))) | O10: =IF($C10="","",INDEX('评级迁移'!$O$2:$O$9,MATCH($C10,'评级迁移'!$A$2:$A$9,0))) | P10: =IF($C10="","",INDEX('评级迁移'!$P$2:$P$9,MATCH($C10,'评级迁移'!$A$2:$A$9,0))) | Q10: =IF($C10="","",INDEX('评级迁移'!$Q$2:$Q$9,MATCH($C10,'评级迁移'!$A$2:$A$9,0))) | R10: =IF($C10="","",INDEX('评级迁移'!$R$2:$R$9,MATCH($C10,'评级迁移'!$A$2:$A$9,0)))
A11: 10 | I11: =IF($C11="","",INDEX('利差假设'!$B$2:$B$9,MATCH($C11,'利差假设'!$A$2:$A$9,0))) | J11: =IF($C11="","",IF($C11="D",$D11*$G11,IF($F11<=1,$D11*(1+$E11),$D11*$E11+IF('参数'!$B$5+$I11=0,$D11+$D11*$E11*($F11-1),$D11*$E11*(1-(1+'参数'!$B$5+$I11)^-($F11-1))/('参数'!$B$5+$I11)+$D11*(1+'参数'!$B$5+$I11)^-($F11-1))))) | K11: =IF($C11="","",INDEX('评级迁移'!$K$2:$K$9,MATCH($C11,'评级迁移'!$A$2:$A$9,0))) | L11: =IF($C11="","",INDEX('评级迁移'!$L$2:$L$9,MATCH($C11,'评级迁移'!$A$2:$A$9,0))) | M11: =IF($C11="","",INDEX('评级迁移'!$M$2:$M$9,MATCH($C11,'评级迁移'!$A$2:$A$9,0))) | N11: =IF($C11="","",INDEX('评级迁移'!$N$2:$N$9,MATCH($C11,'评级迁移'!$A$2:$A$9,0))) | O11: =IF($C11="","",INDEX('评级迁移'!$O$2:$O$9,MATCH($C11,'评级迁移'!$A$2:$A$9,0))) | P11: =IF($C11="","",INDEX('评级迁移'!$P$2:$P$9,MATCH($C11,'评级迁移'!$A$2:$A$9,0))) | Q11: =IF($C11="","",INDEX('评级迁移'!$Q$2:$Q$9,MATCH($C11,'评级迁移'!$A$2:$A$9,0))) | R11: =IF($C11="","",INDEX('评级迁移'!$R$2:$R$9,MATCH($C11,'评级迁移'!$A$2:$A$9,0)))

Sheet 状态价值
A1: 序号 | B1: 债项名称 | C1: 当前评级 | D1: AAA | E1: AA | F1: A | G1: BBB | H1: BB | I1: B | J1: CCC | K1: D | L1: 解析期望价值 | M1: 解析波动率 | N1: 期望损失 | O1: 最差状态损失
A2: ='组合输入'!A2 | B2: ='组合输入'!B2 | C2: ='组合输入'!C2 | D2: =IF($C2="","",IF(D$1="D",'组合输入'!$D2*'组合输入'!$G2,IF('组合输入'!$F2<=1,'组合输入'!$D2*(1+'组合输入'!$E2),'组合输入'!$D2*'组合输入'!$E2+IF('参数'!$B$5+INDEX('利差假设'!$B$2:$B$9,MATCH(D$1,'利差假设'!$A$2:$A$9,0))=0,'组合输入'!$D2+'组合输入'!$D2*'组合输入'!$E2*('组合输入'!$F2-1),'组合输入'!$D2*'组合输入'!$E2*(1-(1+'参数'!$B$5+INDEX('利差假设'!$B$2:$B$9,MATCH(D$1,'利差假设'!$A$2:$A$9,0)))^-('组合输入'!$F2-1))/('参数'!$B$5+INDEX('利差假设'!$B$2:$B$9,MATCH(D$1,'利差假设'!$A$2:$A$9,0)))+'组合输入'!$D2*(1+'参数'!$B$5+INDEX('利差假设'!$B$2:$B$9,MATCH(D$1,'利差假设'!$A$2:$A$9,0)))^-('组合输入'!$F2-1))))) | E2: =IF($C2="","",IF(E$1="D",'组合输入'!$D2*'组合输入'!$G2,IF('组合输入'!$F2<=1,'组合输入'!$D2*(1+'组合输入'!$E2),'组合输入'!$D2*'组合输入'!$E2+IF('参数'!$B$5+INDEX('利差假设'!$B$2:$B$9,MATCH(E$1,'利差假设'!$A$2:$A$9,0))=0,'组合输入'!$D2+'组合输入'!$D2*'组合输入'!$E2*('组合输入'!$F2-1),'组合输入'!$D2*'组合输入'!$E2*(1-(1+'参数'!$B$5+INDEX('利差假设'!$B$2:$B$9,MATCH(E$1,'利差假设'!$A$2:$A$9,0)))^-('组合输入'!$F2-1))/('参数'!$B$5+INDEX('利差假设'!$B$2:$B$9,MATCH(E$1,'利差假设'!$A$2:$A$9,0)))+'组合输入'!$D2*(1+'参数'!$B$5+INDEX('利差假设'!$B$2:$B$9,MATCH(E$1,'利差假设'!$A$2:$A$9,0)))^-('组合输入'!$F2-1))))) | F2: =IF($C2="","",IF(F$1="D",'组合输入'!$D2*'组合输入'!$G2,IF('组合输入'!$F2<=1,'组合输入'!$D2*(1+'组合输入'!$E2),'组合输入'!$D2*'组合输入'!$E2+IF('参数'!$B$5+INDEX('利差假设'!$B$2:$B$9,MATCH(F$1,'利差假设'!$A$2:$A$9,0))=0,'组合输入'!$D2+'组合输入'!$D2*'组合输入'!$E2*('组合输入'!$F2-1),'组合输入'!$D2*'组合输入'!$E2*(1-(1+'参数'!$B$5+INDEX('利差假设'!$B$2:$B$9,MATCH(F$1,'利差假设'!$A$2:$A$9,0)))^-('组合输入'!$F2-1))/('参数'!$B$5+INDEX('利差假设'!$B$2:$B$9,MATCH(F$1,'利差假设'!$A$2:$A$9,0)))+'组合输入'!$D2*(1+'参数'!$B$5+INDEX('利差假设'!$B$2:$B$9,MATCH(F$1,'利差假设'!$A$2:$A$9,0)))^-('组合输入'!$F2-1))))) | G2: =IF($C2="","",IF(G$1="D",'组合输入'!$D2*'组合输入'!$G2,IF('组合输入'!$F2<=1,'组合输入'!$D2*(1+'组合输入'!$E2),'组合输入'!$D2*'组合输入'!$E2+IF('参数'!$B$5+INDEX('利差假设'!$B$2:$B$9,MATCH(G$1,'利差假设'!$A$2:$A$9,0))=0,'组合输入'!$D2+'组合输入'!$D2*'组合输入'!$E2*('组合输入'!$F2-1),'组合输入'!$D2*'组合输入'!$E2*(1-(1+'参数'!$B$5+INDEX('利差假设'!$B$2:$B$9,MATCH(G$1,'利差假设'!$A$2:$A$9,0)))^-('组合输入'!$F2-1))/('参数'!$B$5+INDEX('利差假设'!$B$2:$B$9,MATCH(G$1,'利差假设'!$A$2:$A$9,0)))+'组合输入'!$D2*(1+'参数'!$B$5+INDEX('利差假设'!$B$2:$B$9,MATCH(G$1,'利差假设'!$A$2:$A$9,0)))^-('组合输入'!$F2-1))))) | H2: =IF($C2="","",IF(H$1="D",'组合输入'!$D2*'组合输入'!$G2,IF('组合输入'!$F2<=1,'组合输入'!$D2*(1+'组合输入'!$E2),'组合输入'!$D2*'组合输入'!$E2+IF('参数'!$B$5+INDEX('利差假设'!$B$2:$B$9,MATCH(H$1,'利差假设'!$A$2:$A$9,0))=0,'组合输入'!$D2+'组合输入'!$D2*'组合输入'!$E2*('组合输入'!$F2-1),'组合输入'!$D2*'组合输入'!$E2*(1-(1+'参数'!$B$5+INDEX('利差假设'!$B$2:$B$9,MATCH(H$1,'利差假设'!$A$2:$A$9,0)))^-('组合输入'!$F2-1))/('参数'!$B$5+INDEX('利差假设'!$B$2:$B$9,MATCH(H$1,'利差假设'!$A$2:$A$9,0)))+'组合输入'!$D2*(1+'参数'!$B$5+INDEX('利差假设'!$B$2:$B$9,MATCH(H$1,'利差假设'!$A$2:$A$9,0)))^-('组合输入'!$F2-1))))) | I2: =IF($C2="","",IF(I$1="D",'组合输入'!$D2*'组合输入'!$G2,IF('组合输入'!$F2<=1,'组合输入'!$D2*(1+'组合输入'!$E2),'组合输入'!$D2*'组合输入'!$E2+IF('参数'!$B$5+INDEX('利差假设'!$B$2:$B$9,MATCH(I$1,'利差假设'!$A$2:$A$9,0))=0,'组合输入'!$D2+'组合输入'!$D2*'组合输入'!$E2*('组合输入'!$F2-1),'组合输入'!$D2*'组合输入'!$E2*(1-(1+'参数'!$B$5+INDEX('利差假设'!$B$2:$B$9,MATCH(I$1,'利差假设'!$A$2:$A$9,0)))^-('组合输入'!$F2-1))/('参数'!$B$5+INDEX('利差假设'!$B$2:$B$9,MATCH(I$1,'利差假设'!$A$2:$A$9,0)))+'组合输入'!$D2*(1+'参数'!$B$5+INDEX('利差假设'!$B$2:$B$9,MATCH(I$1,'利差假设'!$A$2:$A$9,0)))^-('组合输入'!$F2-1))))) | J2: =IF($C2="","",IF(J$1="D",'组合输入'!$D2*'组合输入'!$G2,IF('组合输入'!$F2<=1,'组合输入'!$D2*(1+'组合输入'!$E2),'组合输入'!$D2*'组合输入'!$E2+IF('参数'!$B$5+INDEX('利差假设'!$B$2:$B$9,MATCH(J$1,'利差假设'!$A$2:$A$9,0))=0,'组合输入'!$D2+'组合输入'!$D2*'组合输入'!$E2*('组合输入'!$F2-1),'组合输入'!$D2*'组合输入'!$E2*(1-(1+'参数'!$B$5+INDEX('利差假设'!$B$2:$B$9,MATCH(J$1,'利差假设'!$A$2:$A$9,0)))^-('组合输入'!$F2-1))/('参数'!$B$5+INDEX('利差假设'!$B$2:$B$9,MATCH(J$1,'利差假设'!$A$2:$A$9,0)))+'组合输入'!$D2*(1+'参数'!$B$5+INDEX('利差假设'!$B$2:$B$9,MATCH(J$1,'利差假设'!$A$2:$A$9,0)))^-('组合输入'!$F2-1))))) | K2: =IF($C2="","",IF(K$1="D",'组合输入'!$D2*'组合输入'!$G2,IF('组合输入'!$F2<=1,'组合输入'!$D2*(1+'组合输入'!$E2),'组合输入'!$D2*'组合输入'!$E2+IF('参数'!$B$5+INDEX('利差假设'!$B$2:$B$9,MATCH(K$1,'利差假设'!$A$2:$A$9,0))=0,'组合输入'!$D2+'组合输入'!$D2*'组合输入'!$E2*('组合输入'!$F2-1),'组合输入'!$D2*'组合输入'!$E2*(1-(1+'参数'!$B$5+INDEX('利差假设'!$B$2:$B$9,MATCH(K$1,'利差假设'!$A$2:$A$9,0)))^-('组合输入'!$F2-1))/('参数'!$B$5+INDEX('利差假设'!$B$2:$B$9,MATCH(K$1,'利差假设'!$A$2:$A$9,0)))+'组合输入'!$D2*(1+'参数'!$B$5+INDEX('利差假设'!$B$2:$B$9,MATCH(K$1,'利差假设'!$A$2:$A$9,0)))^-('组合输入'!$F2-1))))) | L2: =IF($C2="","",SUMPRODUCT(INDEX('评级迁移'!$B$2:$I$9,MATCH($C2,'评级迁移'!$A$2:$A$9,0),0),$D2:$K2)) | M2: =IF($C2="","",SQRT(SUMPRODUCT(INDEX('评级迁移'!$B$2:$I$9,MATCH($C2,'评级迁移'!$A$2:$A$9,0),0),($D2:$K2-$L2)*($D2:$K2-$L2)))) | N2: =IF($C2="","",'组合输入'!$J2-$L2) | O2: =IF($C2="","",'组合输入'!$J2-MIN($D2:$K2))
A3: ='组合输入'!A3 | B3: ='组合输入'!B3 | C3: ='组合输入'!C3 | D3: =IF($C3="","",IF(D$1="D",'组合输入'!$D3*'组合输入'!$G3,IF('组合输入'!$F3<=1,'组合输入'!$D3*(1+'组合输入'!$E3),'组合输入'!$D3*'组合输入'!$E3+IF('参数'!$B$5+INDEX('利差假设'!$B$2:$B$9,MATCH(D$1,'利差假设'!$A$2:$A$9,0))=0,'组合输入'!$D3+'组合输入'!$D3*'组合输入'!$E3*('组合输入'!$F3-1),'组合输入'!$D3*'组合输入'!$E3*(1-(1+'参数'!$B$5+INDEX('利差假设'!$B$2:$B$9,MATCH(D$1,'利差假设'!$A$2:$A$9,0)))^-('组合输入'!$F3-1))/('参数'!$B$5+INDEX('利差假设'!$B$2:$B$9,MATCH(D$1,'利差假设'!$A$2:$A$9,0)))+'组合输入'!$D3*(1+'参数'!$B$5+INDEX('利差假设'!$B$2:$B$9,MATCH(D$1,'利差假设'!$A$2:$A$9,0)))^-('组合输入'!$F3-1))))) | E3: =IF($C3="","",IF(E$1="D",'组合输入'!$D3*'组合输入'!$G3,IF('组合输入'!$F3<=1,'组合输入'!$D3*(1+'组合输入'!$E3),'组合输入'!$D3*'组合输入'!$E3+IF('参数'!$B$5+INDEX('利差假设'!$B$2:$B$9,MATCH(E$1,'利差假设'!$A$2:$A$9,0))=0,'组合输入'!$D3+'组合输入'!$D3*'组合输入'!$E3*('组合输入'!$F3-1),'组合输入'!$D3*'组合输入'!$E3*(1-(1+'参数'!$B$5+INDEX('利差假设'!$B$2:$B$9,MATCH(E$1,'利差假设'!$A$2:$A$9,0)))^-('组合输入'!$F3-1))/('参数'!$B$5+INDEX('利差假设'!$B$2:$B$9,MATCH(E$1,'利差假设'!$A$2:$A$9,0)))+'组合输入'!$D3*(1+'参数'!$B$5+INDEX('利差假设'!$B$2:$B$9,MATCH(E$1,'利差假设'!$A$2:$A$9,0)))^-('组合输入'!$F3-1))))) | F3: =IF($C3="","",IF(F$1="D",'组合输入'!$D3*'组合输入'!$G3,IF('组合输入'!$F3<=1,'组合输入'!$D3*(1+'组合输入'!$E3),'组合输入'!$D3*'组合输入'!$E3+IF('参数'!$B$5+INDEX('利差假设'!$B$2:$B$9,MATCH(F$1,'利差假设'!$A$2:$A$9,0))=0,'组合输入'!$D3+'组合输入'!$D3*'组合输入'!$E3*('组合输入'!$F3-1),'组合输入'!$D3*'组合输入'!$E3*(1-(1+'参数'!$B$5+INDEX('利差假设'!$B$2:$B$9,MATCH(F$1,'利差假设'!$A$2:$A$9,0)))^-('组合输入'!$F3-1))/('参数'!$B$5+INDEX('利差假设'!$B$2:$B$9,MATCH(F$1,'利差假设'!$A$2:$A$9,0)))+'组合输入'!$D3*(1+'参数'!$B$5+INDEX('利差假设'!$B$2:$B$9,MATCH(F$1,'利差假设'!$A$2:$A$9,0)))^-('组合输入'!$F3-1))))) | G3: =IF($C3="","",IF(G$1="D",'组合输入'!$D3*'组合输入'!$G3,IF('组合输入'!$F3<=1,'组合输入'!$D3*(1+'组合输入'!$E3),'组合输入'!$D3*'组合输入'!$E3+IF('参数'!$B$5+INDEX('利差假设'!$B$2:$B$9,MATCH(G$1,'利差假设'!$A$2:$A$9,0))=0,'组合输入'!$D3+'组合输入'!$D3*'组合输入'!$E3*('组合输入'!$F3-1),'组合输入'!$D3*'组合输入'!$E3*(1-(1+'参数'!$B$5+INDEX('利差假设'!$B$2:$B$9,MATCH(G$1,'利差假设'!$A$2:$A$9,0)))^-('组合输入'!$F3-1))/('参数'!$B$5+INDEX('利差假设'!$B$2:$B$9,MATCH(G$1,'利差假设'!$A$2:$A$9,0)))+'组合输入'!$D3*(1+'参数'!$B$5+INDEX('利差假设'!$B$2:$B$9,MATCH(G$1,'利差假设'!$A$2:$A$9,0)))^-('组合输入'!$F3-1))))) | H3: =IF($C3="","",IF(H$1="D",'组合输入'!$D3*'组合输入'!$G3,IF('组合输入'!$F3<=1,'组合输入'!$D3*(1+'组合输入'!$E3),'组合输入'!$D3*'组合输入'!$E3+IF('参数'!$B$5+INDEX('利差假设'!$B$2:$B$9,MATCH(H$1,'利差假设'!$A$2:$A$9,0))=0,'组合输入'!$D3+'组合输入'!$D3*'组合输入'!$E3*('组合输入'!$F3-1),'组合输入'!$D3*'组合输入'!$E3*(1-(1+'参数'!$B$5+INDEX('利差假设'!$B$2:$B$9,MATCH(H$1,'利差假设'!$A$2:$A$9,0)))^-('组合输入'!$F3-1))/('参数'!$B$5+INDEX('利差假设'!$B$2:$B$9,MATCH(H$1,'利差假设'!$A$2:$A$9,0)))+'组合输入'!$D3*(1+'参数'!$B$5+INDEX('利差假设'!$B$2:$B$9,MATCH(H$1,'利差假设'!$A$2:$A$9,0)))^-('组合输入'!$F3-1))))) | I3: =IF($C3="","",IF(I$1="D",'组合输入'!$D3*'组合输入'!$G3,IF('组合输入'!$F3<=1,'组合输入'!$D3*(1+'组合输入'!$E3),'组合输入'!$D3*'组合输入'!$E3+IF('参数'!$B$5+INDEX('利差假设'!$B$2:$B$9,MATCH(I$1,'利差假设'!$A$2:$A$9,0))=0,'组合输入'!$D3+'组合输入'!$D3*'组合输入'!$E3*('组合输入'!$F3-1),'组合输入'!$D3*'组合输入'!$E3*(1-(1+'参数'!$B$5+INDEX('利差假设'!$B$2:$B$9,MATCH(I$1,'利差假设'!$A$2:$A$9,0)))^-('组合输入'!$F3-1))/('参数'!$B$5+INDEX('利差假设'!$B$2:$B$9,MATCH(I$1,'利差假设'!$A$2:$A$9,0)))+'组合输入'!$D3*(1+'参数'!$B$5+INDEX('利差假设'!$B$2:$B$9,MATCH(I$1,'利差假设'!$A$2:$A$9,0)))^-('组合输入'!$F3-1))))) | J3: =IF($C3="","",IF(J$1="D",'组合输入'!$D3*'组合输入'!$G3,IF('组合输入'!$F3<=1,'组合输入'!$D3*(1+'组合输入'!$E3),'组合输入'!$D3*'组合输入'!$E3+IF('参数'!$B$5+INDEX('利差假设'!$B$2:$B$9,MATCH(J$1,'利差假设'!$A$2:$A$9,0))=0,'组合输入'!$D3+'组合输入'!$D3*'组合输入'!$E3*('组合输入'!$F3-1),'组合输入'!$D3*'组合输入'!$E3*(1-(1+'参数'!$B$5+INDEX('利差假设'!$B$2:$B$9,MATCH(J$1,'利差假设'!$A$2:$A$9,0)))^-('组合输入'!$F3-1))/('参数'!$B$5+INDEX('利差假设'!$B$2:$B$9,MATCH(J$1,'利差假设'!$A$2:$A$9,0)))+'组合输入'!$D3*(1+'参数'!$B$5+INDEX('利差假设'!$B$2:$B$9,MATCH(J$1,'利差假设'!$A$2:$A$9,0)))^-('组合输入'!$F3-1))))) | K3: =IF($C3="","",IF(K$1="D",'组合输入'!$D3*'组合输入'!$G3,IF('组合输入'!$F3<=1,'组合输入'!$D3*(1+'组合输入'!$E3),'组合输入'!$D3*'组合输入'!$E3+IF('参数'!$B$5+INDEX('利差假设'!$B$2:$B$9,MATCH(K$1,'利差假设'!$A$2:$A$9,0))=0,'组合输入'!$D3+'组合输入'!$D3*'组合输入'!$E3*('组合输入'!$F3-1),'组合输入'!$D3*'组合输入'!$E3*(1-(1+'参数'!$B$5+INDEX('利差假设'!$B$2:$B$9,MATCH(K$1,'利差假设'!$A$2:$A$9,0)))^-('组合输入'!$F3-1))/('参数'!$B$5+INDEX('利差假设'!$B$2:$B$9,MATCH(K$1,'利差假设'!$A$2:$A$9,0)))+'组合输入'!$D3*(1+'参数'!$B$5+INDEX('利差假设'!$B$2:$B$9,MATCH(K$1,'利差假设'!$A$2:$A$9,0)))^-('组合输入'!$F3-1))))) | L3: =IF($C3="","",SUMPRODUCT(INDEX('评级迁移'!$B$2:$I$9,MATCH($C3,'评级迁移'!$A$2:$A$9,0),0),$D3:$K3)) | M3: =IF($C3="","",SQRT(SUMPRODUCT(INDEX('评级迁移'!$B$2:$I$9,MATCH($C3,'评级迁移'!$A$2:$A$9,0),0),($D3:$K3-$L3)*($D3:$K3-$L3)))) | N3: =IF($C3="","",'组合输入'!$J3-$L3) | O3: =IF($C3="","",'组合输入'!$J3-MIN($D3:$K3))
A4: ='组合输入'!A4 | B4: ='组合输入'!B4 | C4: ='组合输入'!C4 | D4: =IF($C4="","",IF(D$1="D",'组合输入'!$D4*'组合输入'!$G4,IF('组合输入'!$F4<=1,'组合输入'!$D4*(1+'组合输入'!$E4),'组合输入'!$D4*'组合输入'!$E4+IF('参数'!$B$5+INDEX('利差假设'!$B$2:$B$9,MATCH(D$1,'利差假设'!$A$2:$A$9,0))=0,'组合输入'!$D4+'组合输入'!$D4*'组合输入'!$E4*('组合输入'!$F4-1),'组合输入'!$D4*'组合输入'!$E4*(1-(1+'参数'!$B$5+INDEX('利差假设'!$B$2:$B$9,MATCH(D$1,'利差假设'!$A$2:$A$9,0)))^-('组合输入'!$F4-1))/('参数'!$B$5+INDEX('利差假设'!$B$2:$B$9,MATCH(D$1,'利差假设'!$A$2:$A$9,0)))+'组合输入'!$D4*(1+'参数'!$B$5+INDEX('利差假设'!$B$2:$B$9,MATCH(D$1,'利差假设'!$A$2:$A$9,0)))^-('组合输入'!$F4-1))))) | E4: =IF($C4="","",IF(E$1="D",'组合输入'!$D4*'组合输入'!$G4,IF('组合输入'!$F4<=1,'组合输入'!$D4*(1+'组合输入'!$E4),'组合输入'!$D4*'组合输入'!$E4+IF('参数'!$B$5+INDEX('利差假设'!$B$2:$B$9,MATCH(E$1,'利差假设'!$A$2:$A$9,0))=0,'组合输入'!$D4+'组合输入'!$D4*'组合输入'!$E4*('组合输入'!$F4-1),'组合输入'!$D4*'组合输入'!$E4*(1-(1+'参数'!$B$5+INDEX('利差假设'!$B$2:$B$9,MATCH(E$1,'利差假设'!$A$2:$A$9,0)))^-('组合输入'!$F4-1))/('参数'!$B$5+INDEX('利差假设'!$B$2:$B$9,MATCH(E$1,'利差假设'!$A$2:$A$9,0)))+'组合输入'!$D4*(1+'参数'!$B$5+INDEX('利差假设'!$B$2:$B$9,MATCH(E$1,'利差假设'!$A$2:$A$9,0)))^-('组合输入'!$F4-1))))) | F4: =IF($C4="","",IF(F$1="D",'组合输入'!$D4*'组合输入'!$G4,IF('组合输入'!$F4<=1,'组合输入'!$D4*(1+'组合输入'!$E4),'组合输入'!$D4*'组合输入'!$E4+IF('参数'!$B$5+INDEX('利差假设'!$B$2:$B$9,MATCH(F$1,'利差假设'!$A$2:$A$9,0))=0,'组合输入'!$D4+'组合输入'!$D4*'组合输入'!$E4*('组合输入'!$F4-1),'组合输入'!$D4*'组合输入'!$E4*(1-(1+'参数'!$B$5+INDEX('利差假设'!$B$2:$B$9,MATCH(F$1,'利差假设'!$A$2:$A$9,0)))^-('组合输入'!$F4-1))/('参数'!$B$5+INDEX('利差假设'!$B$2:$B$9,MATCH(F$1,'利差假设'!$A$2:$A$9,0)))+'组合输入'!$D4*(1+'参数'!$B$5+INDEX('利差假设'!$B$2:$B$9,MATCH(F$1,'利差假设'!$A$2:$A$9,0)))^-('组合输入'!$F4-1))))) | G4: =IF($C4="","",IF(G$1="D",'组合输入'!$D4*'组合输入'!$G4,IF('组合输入'!$F4<=1,'组合输入'!$D4*(1+'组合输入'!$E4),'组合输入'!$D4*'组合输入'!$E4+IF('参数'!$B$5+INDEX('利差假设'!$B$2:$B$9,MATCH(G$1,'利差假设'!$A$2:$A$9,0))=0,'组合输入'!$D4+'组合输入'!$D4*'组合输入'!$E4*('组合输入'!$F4-1),'组合输入'!$D4*'组合输入'!$E4*(1-(1+'参数'!$B$5+INDEX('利差假设'!$B$2:$B$9,MATCH(G$1,'利差假设'!$A$2:$A$9,0)))^-('组合输入'!$F4-1))/('参数'!$B$5+INDEX('利差假设'!$B$2:$B$9,MATCH(G$1,'利差假设'!$A$2:$A$9,0)))+'组合输入'!$D4*(1+'参数'!$B$5+INDEX('利差假设'!$B$2:$B$9,MATCH(G$1,'利差假设'!$A$2:$A$9,0)))^-('组合输入'!$F4-1))))) | H4: =IF($C4="","",IF(H$1="D",'组合输入'!$D4*'组合输入'!$G4,IF('组合输入'!$F4<=1,'组合输入'!$D4*(1+'组合输入'!$E4),'组合输入'!$D4*'组合输入'!$E4+IF('参数'!$B$5+INDEX('利差假设'!$B$2:$B$9,MATCH(H$1,'利差假设'!$A$2:$A$9,0))=0,'组合输入'!$D4+'组合输入'!$D4*'组合输入'!$E4*('组合输入'!$F4-1),'组合输入'!$D4*'组合输入'!$E4*(1-(1+'参数'!$B$5+INDEX('利差假设'!$B$2:$B$9,MATCH(H$1,'利差假设'!$A$2:$A$9,0)))^-('组合输入'!$F4-1))/('参数'!$B$5+INDEX('利差假设'!$B$2:$B$9,MATCH(H$1,'利差假设'!$A$2:$A$9,0)))+'组合输入'!$D4*(1+'参数'!$B$5+INDEX('利差假设'!$B$2:$B$9,MATCH(H$1,'利差假设'!$A$2:$A$9,0)))^-('组合输入'!$F4-1))))) | I4: =IF($C4="","",IF(I$1="D",'组合输入'!$D4*'组合输入'!$G4,IF('组合输入'!$F4<=1,'组合输入'!$D4*(1+'组合输入'!$E4),'组合输入'!$D4*'组合输入'!$E4+IF('参数'!$B$5+INDEX('利差假设'!$B$2:$B$9,MATCH(I$1,'利差假设'!$A$2:$A$9,0))=0,'组合输入'!$D4+'组合输入'!$D4*'组合输入'!$E4*('组合输入'!$F4-1),'组合输入'!$D4*'组合输入'!$E4*(1-(1+'参数'!$B$5+INDEX('利差假设'!$B$2:$B$9,MATCH(I$1,'利差假设'!$A$2:$A$9,0)))^-('组合输入'!$F4-1))/('参数'!$B$5+INDEX('利差假设'!$B$2:$B$9,MATCH(I$1,'利差假设'!$A$2:$A$9,0)))+'组合输入'!$D4*(1+'参数'!$B$5+INDEX('利差假设'!$B$2:$B$9,MATCH(I$1,'利差假设'!$A$2:$A$9,0)))^-('组合输入'!$F4-1))))) | J4: =IF($C4="","",IF(J$1="D",'组合输入'!$D4*'组合输入'!$G4,IF('组合输入'!$F4<=1,'组合输入'!$D4*(1+'组合输入'!$E4),'组合输入'!$D4*'组合输入'!$E4+IF('参数'!$B$5+INDEX('利差假设'!$B$2:$B$9,MATCH(J$1,'利差假设'!$A$2:$A$9,0))=0,'组合输入'!$D4+'组合输入'!$D4*'组合输入'!$E4*('组合输入'!$F4-1),'组合输入'!$D4*'组合输入'!$E4*(1-(1+'参数'!$B$5+INDEX('利差假设'!$B$2:$B$9,MATCH(J$1,'利差假设'!$A$2:$A$9,0)))^-('组合输入'!$F4-1))/('参数'!$B$5+INDEX('利差假设'!$B$2:$B$9,MATCH(J$1,'利差假设'!$A$2:$A$9,0)))+'组合输入'!$D4*(1+'参数'!$B$5+INDEX('利差假设'!$B$2:$B$9,MATCH(J$1,'利差假设'!$A$2:$A$9,0)))^-('组合输入'!$F4-1))))) | K4: =IF($C4="","",IF(K$1="D",'组合输入'!$D4*'组合输入'!$G4,IF('组合输入'!$F4<=1,'组合输入'!$D4*(1+'组合输入'!$E4),'组合输入'!$D4*'组合输入'!$E4+IF('参数'!$B$5+INDEX('利差假设'!$B$2:$B$9,MATCH(K$1,'利差假设'!$A$2:$A$9,0))=0,'组合输入'!$D4+'组合输入'!$D4*'组合输入'!$E4*('组合输入'!$F4-1),'组合输入'!$D4*'组合输入'!$E4*(1-(1+'参数'!$B$5+INDEX('利差假设'!$B$2:$B$9,MATCH(K$1,'利差假设'!$A$2:$A$9,0)))^-('组合输入'!$F4-1))/('参数'!$B$5+INDEX('利差假设'!$B$2:$B$9,MATCH(K$1,'利差假设'!$A$2:$A$9,0)))+'组合输入'!$D4*(1+'参数'!$B$5+INDEX('利差假设'!$B$2:$B$9,MATCH(K$1,'利差假设'!$A$2:$A$9,0)))^-('组合输入'!$F4-1))))) | L4: =IF($C4="","",SUMPRODUCT(INDEX('评级迁移'!$B$2:$I$9,MATCH($C4,'评级迁移'!$A$2:$A$9,0),0),$D4:$K4)) | M4: =IF($C4="","",SQRT(SUMPRODUCT(INDEX('评级迁移'!$B$2:$I$9,MATCH($C4,'评级迁移'!$A$2:$A$9,0),0),($D4:$K4-$L4)*($D4:$K4-$L4)))) | N4: =IF($C4="","",'组合输入'!$J4-$L4) | O4: =IF($C4="","",'组合输入'!$J4-MIN($D4:$K4))
A5: ='组合输入'!A5 | B5: ='组合输入'!B5 | C5: ='组合输入'!C5 | D5: =IF($C5="","",IF(D$1="D",'组合输入'!$D5*'组合输入'!$G5,IF('组合输入'!$F5<=1,'组合输入'!$D5*(1+'组合输入'!$E5),'组合输入'!$D5*'组合输入'!$E5+IF('参数'!$B$5+INDEX('利差假设'!$B$2:$B$9,MATCH(D$1,'利差假设'!$A$2:$A$9,0))=0,'组合输入'!$D5+'组合输入'!$D5*'组合输入'!$E5*('组合输入'!$F5-1),'组合输入'!$D5*'组合输入'!$E5*(1-(1+'参数'!$B$5+INDEX('利差假设'!$B$2:$B$9,MATCH(D$1,'利差假设'!$A$2:$A$9,0)))^-('组合输入'!$F5-1))/('参数'!$B$5+INDEX('利差假设'!$B$2:$B$9,MATCH(D$1,'利差假设'!$A$2:$A$9,0)))+'组合输入'!$D5*(1+'参数'!$B$5+INDEX('利差假设'!$B$2:$B$9,MATCH(D$1,'利差假设'!$A$2:$A$9,0)))^-('组合输入'!$F5-1))))) | E5: =IF($C5="","",IF(E$1="D",'组合输入'!$D5*'组合输入'!$G5,IF('组合输入'!$F5<=1,'组合输入'!$D5*(1+'组合输入'!$E5),'组合输入'!$D5*'组合输入'!$E5+IF('参数'!$B$5+INDEX('利差假设'!$B$2:$B$9,MATCH(E$1,'利差假设'!$A$2:$A$9,0))=0,'组合输入'!$D5+'组合输入'!$D5*'组合输入'!$E5*('组合输入'!$F5-1),'组合输入'!$D5*'组合输入'!$E5*(1-(1+'参数'!$B$5+INDEX('利差假设'!$B$2:$B$9,MATCH(E$1,'利差假设'!$A$2:$A$9,0)))^-('组合输入'!$F5-1))/('参数'!$B$5+INDEX('利差假设'!$B$2:$B$9,MATCH(E$1,'利差假设'!$A$2:$A$9,0)))+'组合输入'!$D5*(1+'参数'!$B$5+INDEX('利差假设'!$B$2:$B$9,MATCH(E$1,'利差假设'!$A$2:$A$9,0)))^-('组合输入'!$F5-1))))) | F5: =IF($C5="","",IF(F$1="D",'组合输入'!$D5*'组合输入'!$G5,IF('组合输入'!$F5<=1,'组合输入'!$D5*(1+'组合输入'!$E5),'组合输入'!$D5*'组合输入'!$E5+IF('参数'!$B$5+INDEX('利差假设'!$B$2:$B$9,MATCH(F$1,'利差假设'!$A$2:$A$9,0))=0,'组合输入'!$D5+'组合输入'!$D5*'组合输入'!$E5*('组合输入'!$F5-1),'组合输入'!$D5*'组合输入'!$E5*(1-(1+'参数'!$B$5+INDEX('利差假设'!$B$2:$B$9,MATCH(F$1,'利差假设'!$A$2:$A$9,0)))^-('组合输入'!$F5-1))/('参数'!$B$5+INDEX('利差假设'!$B$2:$B$9,MATCH(F$1,'利差假设'!$A$2:$A$9,0)))+'组合输入'!$D5*(1+'参数'!$B$5+INDEX('利差假设'!$B$2:$B$9,MATCH(F$1,'利差假设'!$A$2:$A$9,0)))^-('组合输入'!$F5-1))))) | G5: =IF($C5="","",IF(G$1="D",'组合输入'!$D5*'组合输入'!$G5,IF('组合输入'!$F5<=1,'组合输入'!$D5*(1+'组合输入'!$E5),'组合输入'!$D5*'组合输入'!$E5+IF('参数'!$B$5+INDEX('利差假设'!$B$2:$B$9,MATCH(G$1,'利差假设'!$A$2:$A$9,0))=0,'组合输入'!$D5+'组合输入'!$D5*'组合输入'!$E5*('组合输入'!$F5-1),'组合输入'!$D5*'组合输入'!$E5*(1-(1+'参数'!$B$5+INDEX('利差假设'!$B$2:$B$9,MATCH(G$1,'利差假设'!$A$2:$A$9,0)))^-('组合输入'!$F5-1))/('参数'!$B$5+INDEX('利差假设'!$B$2:$B$9,MATCH(G$1,'利差假设'!$A$2:$A$9,0)))+'组合输入'!$D5*(1+'参数'!$B$5+INDEX('利差假设'!$B$2:$B$9,MATCH(G$1,'利差假设'!$A$2:$A$9,0)))^-('组合输入'!$F5-1))))) | H5: =IF($C5="","",IF(H$1="D",'组合输入'!$D5*'组合输入'!$G5,IF('组合输入'!$F5<=1,'组合输入'!$D5*(1+'组合输入'!$E5),'组合输入'!$D5*'组合输入'!$E5+IF('参数'!$B$5+INDEX('利差假设'!$B$2:$B$9,MATCH(H$1,'利差假设'!$A$2:$A$9,0))=0,'组合输入'!$D5+'组合输入'!$D5*'组合输入'!$E5*('组合输入'!$F5-1),'组合输入'!$D5*'组合输入'!$E5*(1-(1+'参数'!$B$5+INDEX('利差假设'!$B$2:$B$9,MATCH(H$1,'利差假设'!$A$2:$A$9,0)))^-('组合输入'!$F5-1))/('参数'!$B$5+INDEX('利差假设'!$B$2:$B$9,MATCH(H$1,'利差假设'!$A$2:$A$9,0)))+'组合输入'!$D5*(1+'参数'!$B$5+INDEX('利差假设'!$B$2:$B$9,MATCH(H$1,'利差假设'!$A$2:$A$9,0)))^-('组合输入'!$F5-1))))) | I5: =IF($C5="","",IF(I$1="D",'组合输入'!$D5*'组合输入'!$G5,IF('组合输入'!$F5<=1,'组合输入'!$D5*(1+'组合输入'!$E5),'组合输入'!$D5*'组合输入'!$E5+IF('参数'!$B$5+INDEX('利差假设'!$B$2:$B$9,MATCH(I$1,'利差假设'!$A$2:$A$9,0))=0,'组合输入'!$D5+'组合输入'!$D5*'组合输入'!$E5*('组合输入'!$F5-1),'组合输入'!$D5*'组合输入'!$E5*(1-(1+'参数'!$B$5+INDEX('利差假设'!$B$2:$B$9,MATCH(I$1,'利差假设'!$A$2:$A$9,0)))^-('组合输入'!$F5-1))/('参数'!$B$5+INDEX('利差假设'!$B$2:$B$9,MATCH(I$1,'利差假设'!$A$2:$A$9,0)))+'组合输入'!$D5*(1+'参数'!$B$5+INDEX('利差假设'!$B$2:$B$9,MATCH(I$1,'利差假设'!$A$2:$A$9,0)))^-('组合输入'!$F5-1))))) | J5: =IF($C5="","",IF(J$1="D",'组合输入'!$D5*'组合输入'!$G5,IF('组合输入'!$F5<=1,'组合输入'!$D5*(1+'组合输入'!$E5),'组合输入'!$D5*'组合输入'!$E5+IF('参数'!$B$5+INDEX('利差假设'!$B$2:$B$9,MATCH(J$1,'利差假设'!$A$2:$A$9,0))=0,'组合输入'!$D5+'组合输入'!$D5*'组合输入'!$E5*('组合输入'!$F5-1),'组合输入'!$D5*'组合输入'!$E5*(1-(1+'参数'!$B$5+INDEX('利差假设'!$B$2:$B$9,MATCH(J$1,'利差假设'!$A$2:$A$9,0)))^-('组合输入'!$F5-1))/('参数'!$B$5+INDEX('利差假设'!$B$2:$B$9,MATCH(J$1,'利差假设'!$A$2:$A$9,0)))+'组合输入'!$D5*(1+'参数'!$B$5+INDEX('利差假设'!$B$2:$B$9,MATCH(J$1,'利差假设'!$A$2:$A$9,0)))^-('组合输入'!$F5-1))))) | K5: =IF($C5="","",IF(K$1="D",'组合输入'!$D5*'组合输入'!$G5,IF('组合输入'!$F5<=1,'组合输入'!$D5*(1+'组合输入'!$E5),'组合输入'!$D5*'组合输入'!$E5+IF('参数'!$B$5+INDEX('利差假设'!$B$2:$B$9,MATCH(K$1,'利差假设'!$A$2:$A$9,0))=0,'组合输入'!$D5+'组合输入'!$D5*'组合输入'!$E5*('组合输入'!$F5-1),'组合输入'!$D5*'组合输入'!$E5*(1-(1+'参数'!$B$5+INDEX('利差假设'!$B$2:$B$9,MATCH(K$1,'利差假设'!$A$2:$A$9,0)))^-('组合输入'!$F5-1))/('参数'!$B$5+INDEX('利差假设'!$B$2:$B$9,MATCH(K$1,'利差假设'!$A$2:$A$9,0)))+'组合输入'!$D5*(1+'参数'!$B$5+INDEX('利差假设'!$B$2:$B$9,MATCH(K$1,'利差假设'!$A$2:$A$9,0)))^-('组合输入'!$F5-1))))) | L5: =IF($C5="","",SUMPRODUCT(INDEX('评级迁移'!$B$2:$I$9,MATCH($C5,'评级迁移'!$A$2:$A$9,0),0),$D5:$K5)) | M5: =IF($C5="","",SQRT(SUMPRODUCT(INDEX('评级迁移'!$B$2:$I$9,MATCH($C5,'评级迁移'!$A$2:$A$9,0),0),($D5:$K5-$L5)*($D5:$K5-$L5)))) | N5: =IF($C5="","",'组合输入'!$J5-$L5) | O5: =IF($C5="","",'组合输入'!$J5-MIN($D5:$K5))
A6: ='组合输入'!A6 | B6: ='组合输入'!B6 | C6: ='组合输入'!C6 | D6: =IF($C6="","",IF(D$1="D",'组合输入'!$D6*'组合输入'!$G6,IF('组合输入'!$F6<=1,'组合输入'!$D6*(1+'组合输入'!$E6),'组合输入'!$D6*'组合输入'!$E6+IF('参数'!$B$5+INDEX('利差假设'!$B$2:$B$9,MATCH(D$1,'利差假设'!$A$2:$A$9,0))=0,'组合输入'!$D6+'组合输入'!$D6*'组合输入'!$E6*('组合输入'!$F6-1),'组合输入'!$D6*'组合输入'!$E6*(1-(1+'参数'!$B$5+INDEX('利差假设'!$B$2:$B$9,MATCH(D$1,'利差假设'!$A$2:$A$9,0)))^-('组合输入'!$F6-1))/('参数'!$B$5+INDEX('利差假设'!$B$2:$B$9,MATCH(D$1,'利差假设'!$A$2:$A$9,0)))+'组合输入'!$D6*(1+'参数'!$B$5+INDEX('利差假设'!$B$2:$B$9,MATCH(D$1,'利差假设'!$A$2:$A$9,0)))^-('组合输入'!$F6-1))))) | E6: =IF($C6="","",IF(E$1="D",'组合输入'!$D6*'组合输入'!$G6,IF('组合输入'!$F6<=1,'组合输入'!$D6*(1+'组合输入'!$E6),'组合输入'!$D6*'组合输入'!$E6+IF('参数'!$B$5+INDEX('利差假设'!$B$2:$B$9,MATCH(E$1,'利差假设'!$A$2:$A$9,0))=0,'组合输入'!$D6+'组合输入'!$D6*'组合输入'!$E6*('组合输入'!$F6-1),'组合输入'!$D6*'组合输入'!$E6*(1-(1+'参数'!$B$5+INDEX('利差假设'!$B$2:$B$9,MATCH(E$1,'利差假设'!$A$2:$A$9,0)))^-('组合输入'!$F6-1))/('参数'!$B$5+INDEX('利差假设'!$B$2:$B$9,MATCH(E$1,'利差假设'!$A$2:$A$9,0)))+'组合输入'!$D6*(1+'参数'!$B$5+INDEX('利差假设'!$B$2:$B$9,MATCH(E$1,'利差假设'!$A$2:$A$9,0)))^-('组合输入'!$F6-1))))) | F6: =IF($C6="","",IF(F$1="D",'组合输入'!$D6*'组合输入'!$G6,IF('组合输入'!$F6<=1,'组合输入'!$D6*(1+'组合输入'!$E6),'组合输入'!$D6*'组合输入'!$E6+IF('参数'!$B$5+INDEX('利差假设'!$B$2:$B$9,MATCH(F$1,'利差假设'!$A$2:$A$9,0))=0,'组合输入'!$D6+'组合输入'!$D6*'组合输入'!$E6*('组合输入'!$F6-1),'组合输入'!$D6*'组合输入'!$E6*(1-(1+'参数'!$B$5+INDEX('利差假设'!$B$2:$B$9,MATCH(F$1,'利差假设'!$A$2:$A$9,0)))^-('组合输入'!$F6-1))/('参数'!$B$5+INDEX('利差假设'!$B$2:$B$9,MATCH(F$1,'利差假设'!$A$2:$A$9,0)))+'组合输入'!$D6*(1+'参数'!$B$5+INDEX('利差假设'!$B$2:$B$9,MATCH(F$1,'利差假设'!$A$2:$A$9,0)))^-('组合输入'!$F6-1))))) | G6: =IF($C6="","",IF(G$1="D",'组合输入'!$D6*'组合输入'!$G6,IF('组合输入'!$F6<=1,'组合输入'!$D6*(1+'组合输入'!$E6),'组合输入'!$D6*'组合输入'!$E6+IF('参数'!$B$5+INDEX('利差假设'!$B$2:$B$9,MATCH(G$1,'利差假设'!$A$2:$A$9,0))=0,'组合输入'!$D6+'组合输入'!$D6*'组合输入'!$E6*('组合输入'!$F6-1),'组合输入'!$D6*'组合输入'!$E6*(1-(1+'参数'!$B$5+INDEX('利差假设'!$B$2:$B$9,MATCH(G$1,'利差假设'!$A$2:$A$9,0)))^-('组合输入'!$F6-1))/('参数'!$B$5+INDEX('利差假设'!$B$2:$B$9,MATCH(G$1,'利差假设'!$A$2:$A$9,0)))+'组合输入'!$D6*(1+'参数'!$B$5+INDEX('利差假设'!$B$2:$B$9,MATCH(G$1,'利差假设'!$A$2:$A$9,0)))^-('组合输入'!$F6-1))))) | H6: =IF($C6="","",IF(H$1="D",'组合输入'!$D6*'组合输入'!$G6,IF('组合输入'!$F6<=1,'组合输入'!$D6*(1+'组合输入'!$E6),'组合输入'!$D6*'组合输入'!$E6+IF('参数'!$B$5+INDEX('利差假设'!$B$2:$B$9,MATCH(H$1,'利差假设'!$A$2:$A$9,0))=0,'组合输入'!$D6+'组合输入'!$D6*'组合输入'!$E6*('组合输入'!$F6-1),'组合输入'!$D6*'组合输入'!$E6*(1-(1+'参数'!$B$5+INDEX('利差假设'!$B$2:$B$9,MATCH(H$1,'利差假设'!$A$2:$A$9,0)))^-('组合输入'!$F6-1))/('参数'!$B$5+INDEX('利差假设'!$B$2:$B$9,MATCH(H$1,'利差假设'!$A$2:$A$9,0)))+'组合输入'!$D6*(1+'参数'!$B$5+INDEX('利差假设'!$B$2:$B$9,MATCH(H$1,'利差假设'!$A$2:$A$9,0)))^-('组合输入'!$F6-1))))) | I6: =IF($C6="","",IF(I$1="D",'组合输入'!$D6*'组合输入'!$G6,IF('组合输入'!$F6<=1,'组合输入'!$D6*(1+'组合输入'!$E6),'组合输入'!$D6*'组合输入'!$E6+IF('参数'!$B$5+INDEX('利差假设'!$B$2:$B$9,MATCH(I$1,'利差假设'!$A$2:$A$9,0))=0,'组合输入'!$D6+'组合输入'!$D6*'组合输入'!$E6*('组合输入'!$F6-1),'组合输入'!$D6*'组合输入'!$E6*(1-(1+'参数'!$B$5+INDEX('利差假设'!$B$2:$B$9,MATCH(I$1,'利差假设'!$A$2:$A$9,0)))^-('组合输入'!$F6-1))/('参数'!$B$5+INDEX('利差假设'!$B$2:$B$9,MATCH(I$1,'利差假设'!$A$2:$A$9,0)))+'组合输入'!$D6*(1+'参数'!$B$5+INDEX('利差假设'!$B$2:$B$9,MATCH(I$1,'利差假设'!$A$2:$A$9,0)))^-('组合输入'!$F6-1))))) | J6: =IF($C6="","",IF(J$1="D",'组合输入'!$D6*'组合输入'!$G6,IF('组合输入'!$F6<=1,'组合输入'!$D6*(1+'组合输入'!$E6),'组合输入'!$D6*'组合输入'!$E6+IF('参数'!$B$5+INDEX('利差假设'!$B$2:$B$9,MATCH(J$1,'利差假设'!$A$2:$A$9,0))=0,'组合输入'!$D6+'组合输入'!$D6*'组合输入'!$E6*('组合输入'!$F6-1),'组合输入'!$D6*'组合输入'!$E6*(1-(1+'参数'!$B$5+INDEX('利差假设'!$B$2:$B$9,MATCH(J$1,'利差假设'!$A$2:$A$9,0)))^-('组合输入'!$F6-1))/('参数'!$B$5+INDEX('利差假设'!$B$2:$B$9,MATCH(J$1,'利差假设'!$A$2:$A$9,0)))+'组合输入'!$D6*(1+'参数'!$B$5+INDEX('利差假设'!$B$2:$B$9,MATCH(J$1,'利差假设'!$A$2:$A$9,0)))^-('组合输入'!$F6-1))))) | K6: =IF($C6="","",IF(K$1="D",'组合输入'!$D6*'组合输入'!$G6,IF('组合输入'!$F6<=1,'组合输入'!$D6*(1+'组合输入'!$E6),'组合输入'!$D6*'组合输入'!$E6+IF('参数'!$B$5+INDEX('利差假设'!$B$2:$B$9,MATCH(K$1,'利差假设'!$A$2:$A$9,0))=0,'组合输入'!$D6+'组合输入'!$D6*'组合输入'!$E6*('组合输入'!$F6-1),'组合输入'!$D6*'组合输入'!$E6*(1-(1+'参数'!$B$5+INDEX('利差假设'!$B$2:$B$9,MATCH(K$1,'利差假设'!$A$2:$A$9,0)))^-('组合输入'!$F6-1))/('参数'!$B$5+INDEX('利差假设'!$B$2:$B$9,MATCH(K$1,'利差假设'!$A$2:$A$9,0)))+'组合输入'!$D6*(1+'参数'!$B$5+INDEX('利差假设'!$B$2:$B$9,MATCH(K$1,'利差假设'!$A$2:$A$9,0)))^-('组合输入'!$F6-1))))) | L6: =IF($C6="","",SUMPRODUCT(INDEX('评级迁移'!$B$2:$I$9,MATCH($C6,'评级迁移'!$A$2:$A$9,0),0),$D6:$K6)) | M6: =IF($C6="","",SQRT(SUMPRODUCT(INDEX('评级迁移'!$B$2:$I$9,MATCH($C6,'评级迁移'!$A$2:$A$9,0),0),($D6:$K6-$L6)*($D6:$K6-$L6)))) | N6: =IF($C6="","",'组合输入'!$J6-$L6) | O6: =IF($C6="","",'组合输入'!$J6-MIN($D6:$K6))
A7: ='组合输入'!A7 | B7: ='组合输入'!B7 | C7: ='组合输入'!C7 | D7: =IF($C7="","",IF(D$1="D",'组合输入'!$D7*'组合输入'!$G7,IF('组合输入'!$F7<=1,'组合输入'!$D7*(1+'组合输入'!$E7),'组合输入'!$D7*'组合输入'!$E7+IF('参数'!$B$5+INDEX('利差假设'!$B$2:$B$9,MATCH(D$1,'利差假设'!$A$2:$A$9,0))=0,'组合输入'!$D7+'组合输入'!$D7*'组合输入'!$E7*('组合输入'!$F7-1),'组合输入'!$D7*'组合输入'!$E7*(1-(1+'参数'!$B$5+INDEX('利差假设'!$B$2:$B$9,MATCH(D$1,'利差假设'!$A$2:$A$9,0)))^-('组合输入'!$F7-1))/('参数'!$B$5+INDEX('利差假设'!$B$2:$B$9,MATCH(D$1,'利差假设'!$A$2:$A$9,0)))+'组合输入'!$D7*(1+'参数'!$B$5+INDEX('利差假设'!$B$2:$B$9,MATCH(D$1,'利差假设'!$A$2:$A$9,0)))^-('组合输入'!$F7-1))))) | E7: =IF($C7="","",IF(E$1="D",'组合输入'!$D7*'组合输入'!$G7,IF('组合输入'!$F7<=1,'组合输入'!$D7*(1+'组合输入'!$E7),'组合输入'!$D7*'组合输入'!$E7+IF('参数'!$B$5+INDEX('利差假设'!$B$2:$B$9,MATCH(E$1,'利差假设'!$A$2:$A$9,0))=0,'组合输入'!$D7+'组合输入'!$D7*'组合输入'!$E7*('组合输入'!$F7-1),'组合输入'!$D7*'组合输入'!$E7*(1-(1+'参数'!$B$5+INDEX('利差假设'!$B$2:$B$9,MATCH(E$1,'利差假设'!$A$2:$A$9,0)))^-('组合输入'!$F7-1))/('参数'!$B$5+INDEX('利差假设'!$B$2:$B$9,MATCH(E$1,'利差假设'!$A$2:$A$9,0)))+'组合输入'!$D7*(1+'参数'!$B$5+INDEX('利差假设'!$B$2:$B$9,MATCH(E$1,'利差假设'!$A$2:$A$9,0)))^-('组合输入'!$F7-1))))) | F7: =IF($C7="","",IF(F$1="D",'组合输入'!$D7*'组合输入'!$G7,IF('组合输入'!$F7<=1,'组合输入'!$D7*(1+'组合输入'!$E7),'组合输入'!$D7*'组合输入'!$E7+IF('参数'!$B$5+INDEX('利差假设'!$B$2:$B$9,MATCH(F$1,'利差假设'!$A$2:$A$9,0))=0,'组合输入'!$D7+'组合输入'!$D7*'组合输入'!$E7*('组合输入'!$F7-1),'组合输入'!$D7*'组合输入'!$E7*(1-(1+'参数'!$B$5+INDEX('利差假设'!$B$2:$B$9,MATCH(F$1,'利差假设'!$A$2:$A$9,0)))^-('组合输入'!$F7-1))/('参数'!$B$5+INDEX('利差假设'!$B$2:$B$9,MATCH(F$1,'利差假设'!$A$2:$A$9,0)))+'组合输入'!$D7*(1+'参数'!$B$5+INDEX('利差假设'!$B$2:$B$9,MATCH(F$1,'利差假设'!$A$2:$A$9,0)))^-('组合输入'!$F7-1))))) | G7: =IF($C7="","",IF(G$1="D",'组合输入'!$D7*'组合输入'!$G7,IF('组合输入'!$F7<=1,'组合输入'!$D7*(1+'组合输入'!$E7),'组合输入'!$D7*'组合输入'!$E7+IF('参数'!$B$5+INDEX('利差假设'!$B$2:$B$9,MATCH(G$1,'利差假设'!$A$2:$A$9,0))=0,'组合输入'!$D7+'组合输入'!$D7*'组合输入'!$E7*('组合输入'!$F7-1),'组合输入'!$D7*'组合输入'!$E7*(1-(1+'参数'!$B$5+INDEX('利差假设'!$B$2:$B$9,MATCH(G$1,'利差假设'!$A$2:$A$9,0)))^-('组合输入'!$F7-1))/('参数'!$B$5+INDEX('利差假设'!$B$2:$B$9,MATCH(G$1,'利差假设'!$A$2:$A$9,0)))+'组合输入'!$D7*(1+'参数'!$B$5+INDEX('利差假设'!$B$2:$B$9,MATCH(G$1,'利差假设'!$A$2:$A$9,0)))^-('组合输入'!$F7-1))))) | H7: =IF($C7="","",IF(H$1="D",'组合输入'!$D7*'组合输入'!$G7,IF('组合输入'!$F7<=1,'组合输入'!$D7*(1+'组合输入'!$E7),'组合输入'!$D7*'组合输入'!$E7+IF('参数'!$B$5+INDEX('利差假设'!$B$2:$B$9,MATCH(H$1,'利差假设'!$A$2:$A$9,0))=0,'组合输入'!$D7+'组合输入'!$D7*'组合输入'!$E7*('组合输入'!$F7-1),'组合输入'!$D7*'组合输入'!$E7*(1-(1+'参数'!$B$5+INDEX('利差假设'!$B$2:$B$9,MATCH(H$1,'利差假设'!$A$2:$A$9,0)))^-('组合输入'!$F7-1))/('参数'!$B$5+INDEX('利差假设'!$B$2:$B$9,MATCH(H$1,'利差假设'!$A$2:$A$9,0)))+'组合输入'!$D7*(1+'参数'!$B$5+INDEX('利差假设'!$B$2:$B$9,MATCH(H$1,'利差假设'!$A$2:$A$9,0)))^-('组合输入'!$F7-1))))) | I7: =IF($C7="","",IF(I$1="D",'组合输入'!$D7*'组合输入'!$G7,IF('组合输入'!$F7<=1,'组合输入'!$D7*(1+'组合输入'!$E7),'组合输入'!$D7*'组合输入'!$E7+IF('参数'!$B$5+INDEX('利差假设'!$B$2:$B$9,MATCH(I$1,'利差假设'!$A$2:$A$9,0))=0,'组合输入'!$D7+'组合输入'!$D7*'组合输入'!$E7*('组合输入'!$F7-1),'组合输入'!$D7*'组合输入'!$E7*(1-(1+'参数'!$B$5+INDEX('利差假设'!$B$2:$B$9,MATCH(I$1,'利差假设'!$A$2:$A$9,0)))^-('组合输入'!$F7-1))/('参数'!$B$5+INDEX('利差假设'!$B$2:$B$9,MATCH(I$1,'利差假设'!$A$2:$A$9,0)))+'组合输入'!$D7*(1+'参数'!$B$5+INDEX('利差假设'!$B$2:$B$9,MATCH(I$1,'利差假设'!$A$2:$A$9,0)))^-('组合输入'!$F7-1))))) | J7: =IF($C7="","",IF(J$1="D",'组合输入'!$D7*'组合输入'!$G7,IF('组合输入'!$F7<=1,'组合输入'!$D7*(1+'组合输入'!$E7),'组合输入'!$D7*'组合输入'!$E7+IF('参数'!$B$5+INDEX('利差假设'!$B$2:$B$9,MATCH(J$1,'利差假设'!$A$2:$A$9,0))=0,'组合输入'!$D7+'组合输入'!$D7*'组合输入'!$E7*('组合输入'!$F7-1),'组合输入'!$D7*'组合输入'!$E7*(1-(1+'参数'!$B$5+INDEX('利差假设'!$B$2:$B$9,MATCH(J$1,'利差假设'!$A$2:$A$9,0)))^-('组合输入'!$F7-1))/('参数'!$B$5+INDEX('利差假设'!$B$2:$B$9,MATCH(J$1,'利差假设'!$A$2:$A$9,0)))+'组合输入'!$D7*(1+'参数'!$B$5+INDEX('利差假设'!$B$2:$B$9,MATCH(J$1,'利差假设'!$A$2:$A$9,0)))^-('组合输入'!$F7-1))))) | K7: =IF($C7="","",IF(K$1="D",'组合输入'!$D7*'组合输入'!$G7,IF('组合输入'!$F7<=1,'组合输入'!$D7*(1+'组合输入'!$E7),'组合输入'!$D7*'组合输入'!$E7+IF('参数'!$B$5+INDEX('利差假设'!$B$2:$B$9,MATCH(K$1,'利差假设'!$A$2:$A$9,0))=0,'组合输入'!$D7+'组合输入'!$D7*'组合输入'!$E7*('组合输入'!$F7-1),'组合输入'!$D7*'组合输入'!$E7*(1-(1+'参数'!$B$5+INDEX('利差假设'!$B$2:$B$9,MATCH(K$1,'利差假设'!$A$2:$A$9,0)))^-('组合输入'!$F7-1))/('参数'!$B$5+INDEX('利差假设'!$B$2:$B$9,MATCH(K$1,'利差假设'!$A$2:$A$9,0)))+'组合输入'!$D7*(1+'参数'!$B$5+INDEX('利差假设'!$B$2:$B$9,MATCH(K$1,'利差假设'!$A$2:$A$9,0)))^-('组合输入'!$F7-1))))) | L7: =IF($C7="","",SUMPRODUCT(INDEX('评级迁移'!$B$2:$I$9,MATCH($C7,'评级迁移'!$A$2:$A$9,0),0),$D7:$K7)) | M7: =IF($C7="","",SQRT(SUMPRODUCT(INDEX('评级迁移'!$B$2:$I$9,MATCH($C7,'评级迁移'!$A$2:$A$9,0),0),($D7:$K7-$L7)*($D7:$K7-$L7)))) | N7: =IF($C7="","",'组合输入'!$J7-$L7) | O7: =IF($C7="","",'组合输入'!$J7-MIN($D7:$K7))
A8: ='组合输入'!A8 | B8: ='组合输入'!B8 | C8: ='组合输入'!C8 | D8: =IF($C8="","",IF(D$1="D",'组合输入'!$D8*'组合输入'!$G8,IF('组合输入'!$F8<=1,'组合输入'!$D8*(1+'组合输入'!$E8),'组合输入'!$D8*'组合输入'!$E8+IF('参数'!$B$5+INDEX('利差假设'!$B$2:$B$9,MATCH(D$1,'利差假设'!$A$2:$A$9,0))=0,'组合输入'!$D8+'组合输入'!$D8*'组合输入'!$E8*('组合输入'!$F8-1),'组合输入'!$D8*'组合输入'!$E8*(1-(1+'参数'!$B$5+INDEX('利差假设'!$B$2:$B$9,MATCH(D$1,'利差假设'!$A$2:$A$9,0)))^-('组合输入'!$F8-1))/('参数'!$B$5+INDEX('利差假设'!$B$2:$B$9,MATCH(D$1,'利差假设'!$A$2:$A$9,0)))+'组合输入'!$D8*(1+'参数'!$B$5+INDEX('利差假设'!$B$2:$B$9,MATCH(D$1,'利差假设'!$A$2:$A$9,0)))^-('组合输入'!$F8-1))))) | E8: =IF($C8="","",IF(E$1="D",'组合输入'!$D8*'组合输入'!$G8,IF('组合输入'!$F8<=1,'组合输入'!$D8*(1+'组合输入'!$E8),'组合输入'!$D8*'组合输入'!$E8+IF('参数'!$B$5+INDEX('利差假设'!$B$2:$B$9,MATCH(E$1,'利差假设'!$A$2:$A$9,0))=0,'组合输入'!$D8+'组合输入'!$D8*'组合输入'!$E8*('组合输入'!$F8-1),'组合输入'!$D8*'组合输入'!$E8*(1-(1+'参数'!$B$5+INDEX('利差假设'!$B$2:$B$9,MATCH(E$1,'利差假设'!$A$2:$A$9,0)))^-('组合输入'!$F8-1))/('参数'!$B$5+INDEX('利差假设'!$B$2:$B$9,MATCH(E$1,'利差假设'!$A$2:$A$9,0)))+'组合输入'!$D8*(1+'参数'!$B$5+INDEX('利差假设'!$B$2:$B$9,MATCH(E$1,'利差假设'!$A$2:$A$9,0)))^-('组合输入'!$F8-1))))) | F8: =IF($C8="","",IF(F$1="D",'组合输入'!$D8*'组合输入'!$G8,IF('组合输入'!$F8<=1,'组合输入'!$D8*(1+'组合输入'!$E8),'组合输入'!$D8*'组合输入'!$E8+IF('参数'!$B$5+INDEX('利差假设'!$B$2:$B$9,MATCH(F$1,'利差假设'!$A$2:$A$9,0))=0,'组合输入'!$D8+'组合输入'!$D8*'组合输入'!$E8*('组合输入'!$F8-1),'组合输入'!$D8*'组合输入'!$E8*(1-(1+'参数'!$B$5+INDEX('利差假设'!$B$2:$B$9,MATCH(F$1,'利差假设'!$A$2:$A$9,0)))^-('组合输入'!$F8-1))/('参数'!$B$5+INDEX('利差假设'!$B$2:$B$9,MATCH(F$1,'利差假设'!$A$2:$A$9,0)))+'组合输入'!$D8*(1+'参数'!$B$5+INDEX('利差假设'!$B$2:$B$9,MATCH(F$1,'利差假设'!$A$2:$A$9,0)))^-('组合输入'!$F8-1))))) | G8: =IF($C8="","",IF(G$1="D",'组合输入'!$D8*'组合输入'!$G8,IF('组合输入'!$F8<=1,'组合输入'!$D8*(1+'组合输入'!$E8),'组合输入'!$D8*'组合输入'!$E8+IF('参数'!$B$5+INDEX('利差假设'!$B$2:$B$9,MATCH(G$1,'利差假设'!$A$2:$A$9,0))=0,'组合输入'!$D8+'组合输入'!$D8*'组合输入'!$E8*('组合输入'!$F8-1),'组合输入'!$D8*'组合输入'!$E8*(1-(1+'参数'!$B$5+INDEX('利差假设'!$B$2:$B$9,MATCH(G$1,'利差假设'!$A$2:$A$9,0)))^-('组合输入'!$F8-1))/('参数'!$B$5+INDEX('利差假设'!$B$2:$B$9,MATCH(G$1,'利差假设'!$A$2:$A$9,0)))+'组合输入'!$D8*(1+'参数'!$B$5+INDEX('利差假设'!$B$2:$B$9,MATCH(G$1,'利差假设'!$A$2:$A$9,0)))^-('组合输入'!$F8-1))))) | H8: =IF($C8="","",IF(H$1="D",'组合输入'!$D8*'组合输入'!$G8,IF('组合输入'!$F8<=1,'组合输入'!$D8*(1+'组合输入'!$E8),'组合输入'!$D8*'组合输入'!$E8+IF('参数'!$B$5+INDEX('利差假设'!$B$2:$B$9,MATCH(H$1,'利差假设'!$A$2:$A$9,0))=0,'组合输入'!$D8+'组合输入'!$D8*'组合输入'!$E8*('组合输入'!$F8-1),'组合输入'!$D8*'组合输入'!$E8*(1-(1+'参数'!$B$5+INDEX('利差假设'!$B$2:$B$9,MATCH(H$1,'利差假设'!$A$2:$A$9,0)))^-('组合输入'!$F8-1))/('参数'!$B$5+INDEX('利差假设'!$B$2:$B$9,MATCH(H$1,'利差假设'!$A$2:$A$9,0)))+'组合输入'!$D8*(1+'参数'!$B$5+INDEX('利差假设'!$B$2:$B$9,MATCH(H$1,'利差假设'!$A$2:$A$9,0)))^-('组合输入'!$F8-1))))) | I8: =IF($C8="","",IF(I$1="D",'组合输入'!$D8*'组合输入'!$G8,IF('组合输入'!$F8<=1,'组合输入'!$D8*(1+'组合输入'!$E8),'组合输入'!$D8*'组合输入'!$E8+IF('参数'!$B$5+INDEX('利差假设'!$B$2:$B$9,MATCH(I$1,'利差假设'!$A$2:$A$9,0))=0,'组合输入'!$D8+'组合输入'!$D8*'组合输入'!$E8*('组合输入'!$F8-1),'组合输入'!$D8*'组合输入'!$E8*(1-(1+'参数'!$B$5+INDEX('利差假设'!$B$2:$B$9,MATCH(I$1,'利差假设'!$A$2:$A$9,0)))^-('组合输入'!$F8-1))/('参数'!$B$5+INDEX('利差假设'!$B$2:$B$9,MATCH(I$1,'利差假设'!$A$2:$A$9,0)))+'组合输入'!$D8*(1+'参数'!$B$5+INDEX('利差假设'!$B$2:$B$9,MATCH(I$1,'利差假设'!$A$2:$A$9,0)))^-('组合输入'!$F8-1))))) | J8: =IF($C8="","",IF(J$1="D",'组合输入'!$D8*'组合输入'!$G8,IF('组合输入'!$F8<=1,'组合输入'!$D8*(1+'组合输入'!$E8),'组合输入'!$D8*'组合输入'!$E8+IF('参数'!$B$5+INDEX('利差假设'!$B$2:$B$9,MATCH(J$1,'利差假设'!$A$2:$A$9,0))=0,'组合输入'!$D8+'组合输入'!$D8*'组合输入'!$E8*('组合输入'!$F8-1),'组合输入'!$D8*'组合输入'!$E8*(1-(1+'参数'!$B$5+INDEX('利差假设'!$B$2:$B$9,MATCH(J$1,'利差假设'!$A$2:$A$9,0)))^-('组合输入'!$F8-1))/('参数'!$B$5+INDEX('利差假设'!$B$2:$B$9,MATCH(J$1,'利差假设'!$A$2:$A$9,0)))+'组合输入'!$D8*(1+'参数'!$B$5+INDEX('利差假设'!$B$2:$B$9,MATCH(J$1,'利差假设'!$A$2:$A$9,0)))^-('组合输入'!$F8-1))))) | K8: =IF($C8="","",IF(K$1="D",'组合输入'!$D8*'组合输入'!$G8,IF('组合输入'!$F8<=1,'组合输入'!$D8*(1+'组合输入'!$E8),'组合输入'!$D8*'组合输入'!$E8+IF('参数'!$B$5+INDEX('利差假设'!$B$2:$B$9,MATCH(K$1,'利差假设'!$A$2:$A$9,0))=0,'组合输入'!$D8+'组合输入'!$D8*'组合输入'!$E8*('组合输入'!$F8-1),'组合输入'!$D8*'组合输入'!$E8*(1-(1+'参数'!$B$5+INDEX('利差假设'!$B$2:$B$9,MATCH(K$1,'利差假设'!$A$2:$A$9,0)))^-('组合输入'!$F8-1))/('参数'!$B$5+INDEX('利差假设'!$B$2:$B$9,MATCH(K$1,'利差假设'!$A$2:$A$9,0)))+'组合输入'!$D8*(1+'参数'!$B$5+INDEX('利差假设'!$B$2:$B$9,MATCH(K$1,'利差假设'!$A$2:$A$9,0)))^-('组合输入'!$F8-1))))) | L8: =IF($C8="","",SUMPRODUCT(INDEX('评级迁移'!$B$2:$I$9,MATCH($C8,'评级迁移'!$A$2:$A$9,0),0),$D8:$K8)) | M8: =IF($C8="","",SQRT(SUMPRODUCT(INDEX('评级迁移'!$B$2:$I$9,MATCH($C8,'评级迁移'!$A$2:$A$9,0),0),($D8:$K8-$L8)*($D8:$K8-$L8)))) | N8: =IF($C8="","",'组合输入'!$J8-$L8) | O8: =IF($C8="","",'组合输入'!$J8-MIN($D8:$K8))
A9: ='组合输入'!A9 | B9: ='组合输入'!B9 | C9: ='组合输入'!C9 | D9: =IF($C9="","",IF(D$1="D",'组合输入'!$D9*'组合输入'!$G9,IF('组合输入'!$F9<=1,'组合输入'!$D9*(1+'组合输入'!$E9),'组合输入'!$D9*'组合输入'!$E9+IF('参数'!$B$5+INDEX('利差假设'!$B$2:$B$9,MATCH(D$1,'利差假设'!$A$2:$A$9,0))=0,'组合输入'!$D9+'组合输入'!$D9*'组合输入'!$E9*('组合输入'!$F9-1),'组合输入'!$D9*'组合输入'!$E9*(1-(1+'参数'!$B$5+INDEX('利差假设'!$B$2:$B$9,MATCH(D$1,'利差假设'!$A$2:$A$9,0)))^-('组合输入'!$F9-1))/('参数'!$B$5+INDEX('利差假设'!$B$2:$B$9,MATCH(D$1,'利差假设'!$A$2:$A$9,0)))+'组合输入'!$D9*(1+'参数'!$B$5+INDEX('利差假设'!$B$2:$B$9,MATCH(D$1,'利差假设'!$A$2:$A$9,0)))^-('组合输入'!$F9-1))))) | E9: =IF($C9="","",IF(E$1="D",'组合输入'!$D9*'组合输入'!$G9,IF('组合输入'!$F9<=1,'组合输入'!$D9*(1+'组合输入'!$E9),'组合输入'!$D9*'组合输入'!$E9+IF('参数'!$B$5+INDEX('利差假设'!$B$2:$B$9,MATCH(E$1,'利差假设'!$A$2:$A$9,0))=0,'组合输入'!$D9+'组合输入'!$D9*'组合输入'!$E9*('组合输入'!$F9-1),'组合输入'!$D9*'组合输入'!$E9*(1-(1+'参数'!$B$5+INDEX('利差假设'!$B$2:$B$9,MATCH(E$1,'利差假设'!$A$2:$A$9,0)))^-('组合输入'!$F9-1))/('参数'!$B$5+INDEX('利差假设'!$B$2:$B$9,MATCH(E$1,'利差假设'!$A$2:$A$9,0)))+'组合输入'!$D9*(1+'参数'!$B$5+INDEX('利差假设'!$B$2:$B$9,MATCH(E$1,'利差假设'!$A$2:$A$9,0)))^-('组合输入'!$F9-1))))) | F9: =IF($C9="","",IF(F$1="D",'组合输入'!$D9*'组合输入'!$G9,IF('组合输入'!$F9<=1,'组合输入'!$D9*(1+'组合输入'!$E9),'组合输入'!$D9*'组合输入'!$E9+IF('参数'!$B$5+INDEX('利差假设'!$B$2:$B$9,MATCH(F$1,'利差假设'!$A$2:$A$9,0))=0,'组合输入'!$D9+'组合输入'!$D9*'组合输入'!$E9*('组合输入'!$F9-1),'组合输入'!$D9*'组合输入'!$E9*(1-(1+'参数'!$B$5+INDEX('利差假设'!$B$2:$B$9,MATCH(F$1,'利差假设'!$A$2:$A$9,0)))^-('组合输入'!$F9-1))/('参数'!$B$5+INDEX('利差假设'!$B$2:$B$9,MATCH(F$1,'利差假设'!$A$2:$A$9,0)))+'组合输入'!$D9*(1+'参数'!$B$5+INDEX('利差假设'!$B$2:$B$9,MATCH(F$1,'利差假设'!$A$2:$A$9,0)))^-('组合输入'!$F9-1))))) | G9: =IF($C9="","",IF(G$1="D",'组合输入'!$D9*'组合输入'!$G9,IF('组合输入'!$F9<=1,'组合输入'!$D9*(1+'组合输入'!$E9),'组合输入'!$D9*'组合输入'!$E9+IF('参数'!$B$5+INDEX('利差假设'!$B$2:$B$9,MATCH(G$1,'利差假设'!$A$2:$A$9,0))=0,'组合输入'!$D9+'组合输入'!$D9*'组合输入'!$E9*('组合输入'!$F9-1),'组合输入'!$D9*'组合输入'!$E9*(1-(1+'参数'!$B$5+INDEX('利差假设'!$B$2:$B$9,MATCH(G$1,'利差假设'!$A$2:$A$9,0)))^-('组合输入'!$F9-1))/('参数'!$B$5+INDEX('利差假设'!$B$2:$B$9,MATCH(G$1,'利差假设'!$A$2:$A$9,0)))+'组合输入'!$D9*(1+'参数'!$B$5+INDEX('利差假设'!$B$2:$B$9,MATCH(G$1,'利差假设'!$A$2:$A$9,0)))^-('组合输入'!$F9-1))))) | H9: =IF($C9="","",IF(H$1="D",'组合输入'!$D9*'组合输入'!$G9,IF('组合输入'!$F9<=1,'组合输入'!$D9*(1+'组合输入'!$E9),'组合输入'!$D9*'组合输入'!$E9+IF('参数'!$B$5+INDEX('利差假设'!$B$2:$B$9,MATCH(H$1,'利差假设'!$A$2:$A$9,0))=0,'组合输入'!$D9+'组合输入'!$D9*'组合输入'!$E9*('组合输入'!$F9-1),'组合输入'!$D9*'组合输入'!$E9*(1-(1+'参数'!$B$5+INDEX('利差假设'!$B$2:$B$9,MATCH(H$1,'利差假设'!$A$2:$A$9,0)))^-('组合输入'!$F9-1))/('参数'!$B$5+INDEX('利差假设'!$B$2:$B$9,MATCH(H$1,'利差假设'!$A$2:$A$9,0)))+'组合输入'!$D9*(1+'参数'!$B$5+INDEX('利差假设'!$B$2:$B$9,MATCH(H$1,'利差假设'!$A$2:$A$9,0)))^-('组合输入'!$F9-1))))) | I9: =IF($C9="","",IF(I$1="D",'组合输入'!$D9*'组合输入'!$G9,IF('组合输入'!$F9<=1,'组合输入'!$D9*(1+'组合输入'!$E9),'组合输入'!$D9*'组合输入'!$E9+IF('参数'!$B$5+INDEX('利差假设'!$B$2:$B$9,MATCH(I$1,'利差假设'!$A$2:$A$9,0))=0,'组合输入'!$D9+'组合输入'!$D9*'组合输入'!$E9*('组合输入'!$F9-1),'组合输入'!$D9*'组合输入'!$E9*(1-(1+'参数'!$B$5+INDEX('利差假设'!$B$2:$B$9,MATCH(I$1,'利差假设'!$A$2:$A$9,0)))^-('组合输入'!$F9-1))/('参数'!$B$5+INDEX('利差假设'!$B$2:$B$9,MATCH(I$1,'利差假设'!$A$2:$A$9,0)))+'组合输入'!$D9*(1+'参数'!$B$5+INDEX('利差假设'!$B$2:$B$9,MATCH(I$1,'利差假设'!$A$2:$A$9,0)))^-('组合输入'!$F9-1))))) | J9: =IF($C9="","",IF(J$1="D",'组合输入'!$D9*'组合输入'!$G9,IF('组合输入'!$F9<=1,'组合输入'!$D9*(1+'组合输入'!$E9),'组合输入'!$D9*'组合输入'!$E9+IF('参数'!$B$5+INDEX('利差假设'!$B$2:$B$9,MATCH(J$1,'利差假设'!$A$2:$A$9,0))=0,'组合输入'!$D9+'组合输入'!$D9*'组合输入'!$E9*('组合输入'!$F9-1),'组合输入'!$D9*'组合输入'!$E9*(1-(1+'参数'!$B$5+INDEX('利差假设'!$B$2:$B$9,MATCH(J$1,'利差假设'!$A$2:$A$9,0)))^-('组合输入'!$F9-1))/('参数'!$B$5+INDEX('利差假设'!$B$2:$B$9,MATCH(J$1,'利差假设'!$A$2:$A$9,0)))+'组合输入'!$D9*(1+'参数'!$B$5+INDEX('利差假设'!$B$2:$B$9,MATCH(J$1,'利差假设'!$A$2:$A$9,0)))^-('组合输入'!$F9-1))))) | K9: =IF($C9="","",IF(K$1="D",'组合输入'!$D9*'组合输入'!$G9,IF('组合输入'!$F9<=1,'组合输入'!$D9*(1+'组合输入'!$E9),'组合输入'!$D9*'组合输入'!$E9+IF('参数'!$B$5+INDEX('利差假设'!$B$2:$B$9,MATCH(K$1,'利差假设'!$A$2:$A$9,0))=0,'组合输入'!$D9+'组合输入'!$D9*'组合输入'!$E9*('组合输入'!$F9-1),'组合输入'!$D9*'组合输入'!$E9*(1-(1+'参数'!$B$5+INDEX('利差假设'!$B$2:$B$9,MATCH(K$1,'利差假设'!$A$2:$A$9,0)))^-('组合输入'!$F9-1))/('参数'!$B$5+INDEX('利差假设'!$B$2:$B$9,MATCH(K$1,'利差假设'!$A$2:$A$9,0)))+'组合输入'!$D9*(1+'参数'!$B$5+INDEX('利差假设'!$B$2:$B$9,MATCH(K$1,'利差假设'!$A$2:$A$9,0)))^-('组合输入'!$F9-1))))) | L9: =IF($C9="","",SUMPRODUCT(INDEX('评级迁移'!$B$2:$I$9,MATCH($C9,'评级迁移'!$A$2:$A$9,0),0),$D9:$K9)) | M9: =IF($C9="","",SQRT(SUMPRODUCT(INDEX('评级迁移'!$B$2:$I$9,MATCH($C9,'评级迁移'!$A$2:$A$9,0),0),($D9:$K9-$L9)*($D9:$K9-$L9)))) | N9: =IF($C9="","",'组合输入'!$J9-$L9) | O9: =IF($C9="","",'组合输入'!$J9-MIN($D9:$K9))
A10: ='组合输入'!A10 | B10: ='组合输入'!B10 | C10: ='组合输入'!C10 | D10: =IF($C10="","",IF(D$1="D",'组合输入'!$D10*'组合输入'!$G10,IF('组合输入'!$F10<=1,'组合输入'!$D10*(1+'组合输入'!$E10),'组合输入'!$D10*'组合输入'!$E10+IF('参数'!$B$5+INDEX('利差假设'!$B$2:$B$9,MATCH(D$1,'利差假设'!$A$2:$A$9,0))=0,'组合输入'!$D10+'组合输入'!$D10*'组合输入'!$E10*('组合输入'!$F10-1),'组合输入'!$D10*'组合输入'!$E10*(1-(1+'参数'!$B$5+INDEX('利差假设'!$B$2:$B$9,MATCH(D$1,'利差假设'!$A$2:$A$9,0)))^-('组合输入'!$F10-1))/('参数'!$B$5+INDEX('利差假设'!$B$2:$B$9,MATCH(D$1,'利差假设'!$A$2:$A$9,0)))+'组合输入'!$D10*(1+'参数'!$B$5+INDEX('利差假设'!$B$2:$B$9,MATCH(D$1,'利差假设'!$A$2:$A$9,0)))^-('组合输入'!$F10-1))))) | E10: =IF($C10="","",IF(E$1="D",'组合输入'!$D10*'组合输入'!$G10,IF('组合输入'!$F10<=1,'组合输入'!$D10*(1+'组合输入'!$E10),'组合输入'!$D10*'组合输入'!$E10+IF('参数'!$B$5+INDEX('利差假设'!$B$2:$B$9,MATCH(E$1,'利差假设'!$A$2:$A$9,0))=0,'组合输入'!$D10+'组合输入'!$D10*'组合输入'!$E10*('组合输入'!$F10-1),'组合输入'!$D10*'组合输入'!$E10*(1-(1+'参数'!$B$5+INDEX('利差假设'!$B$2:$B$9,MATCH(E$1,'利差假设'!$A$2:$A$9,0)))^-('组合输入'!$F10-1))/('参数'!$B$5+INDEX('利差假设'!$B$2:$B$9,MATCH(E$1,'利差假设'!$A$2:$A$9,0)))+'组合输入'!$D10*(1+'参数'!$B$5+INDEX('利差假设'!$B$2:$B$9,MATCH(E$1,'利差假设'!$A$2:$A$9,0)))^-('组合输入'!$F10-1))))) | F10: =IF($C10="","",IF(F$1="D",'组合输入'!$D10*'组合输入'!$G10,IF('组合输入'!$F10<=1,'组合输入'!$D10*(1+'组合输入'!$E10),'组合输入'!$D10*'组合输入'!$E10+IF('参数'!$B$5+INDEX('利差假设'!$B$2:$B$9,MATCH(F$1,'利差假设'!$A$2:$A$9,0))=0,'组合输入'!$D10+'组合输入'!$D10*'组合输入'!$E10*('组合输入'!$F10-1),'组合输入'!$D10*'组合输入'!$E10*(1-(1+'参数'!$B$5+INDEX('利差假设'!$B$2:$B$9,MATCH(F$1,'利差假设'!$A$2:$A$9,0)))^-('组合输入'!$F10-1))/('参数'!$B$5+INDEX('利差假设'!$B$2:$B$9,MATCH(F$1,'利差假设'!$A$2:$A$9,0)))+'组合输入'!$D10*(1+'参数'!$B$5+INDEX('利差假设'!$B$2:$B$9,MATCH(F$1,'利差假设'!$A$2:$A$9,0)))^-('组合输入'!$F10-1))))) | G10: =IF($C10="","",IF(G$1="D",'组合输入'!$D10*'组合输入'!$G10,IF('组合输入'!$F10<=1,'组合输入'!$D10*(1+'组合输入'!$E10),'组合输入'!$D10*'组合输入'!$E10+IF('参数'!$B$5+INDEX('利差假设'!$B$2:$B$9,MATCH(G$1,'利差假设'!$A$2:$A$9,0))=0,'组合输入'!$D10+'组合输入'!$D10*'组合输入'!$E10*('组合输入'!$F10-1),'组合输入'!$D10*'组合输入'!$E10*(1-(1+'参数'!$B$5+INDEX('利差假设'!$B$2:$B$9,MATCH(G$1,'利差假设'!$A$2:$A$9,0)))^-('组合输入'!$F10-1))/('参数'!$B$5+INDEX('利差假设'!$B$2:$B$9,MATCH(G$1,'利差假设'!$A$2:$A$9,0)))+'组合输入'!$D10*(1+'参数'!$B$5+INDEX('利差假设'!$B$2:$B$9,MATCH(G$1,'利差假设'!$A$2:$A$9,0)))^-('组合输入'!$F10-1))))) | H10: =IF($C10="","",IF(H$1="D",'组合输入'!$D10*'组合输入'!$G10,IF('组合输入'!$F10<=1,'组合输入'!$D10*(1+'组合输入'!$E10),'组合输入'!$D10*'组合输入'!$E10+IF('参数'!$B$5+INDEX('利差假设'!$B$2:$B$9,MATCH(H$1,'利差假设'!$A$2:$A$9,0))=0,'组合输入'!$D10+'组合输入'!$D10*'组合输入'!$E10*('组合输入'!$F10-1),'组合输入'!$D10*'组合输入'!$E10*(1-(1+'参数'!$B$5+INDEX('利差假设'!$B$2:$B$9,MATCH(H$1,'利差假设'!$A$2:$A$9,0)))^-('组合输入'!$F10-1))/('参数'!$B$5+INDEX('利差假设'!$B$2:$B$9,MATCH(H$1,'利差假设'!$A$2:$A$9,0)))+'组合输入'!$D10*(1+'参数'!$B$5+INDEX('利差假设'!$B$2:$B$9,MATCH(H$1,'利差假设'!$A$2:$A$9,0)))^-('组合输入'!$F10-1))))) | I10: =IF($C10="","",IF(I$1="D",'组合输入'!$D10*'组合输入'!$G10,IF('组合输入'!$F10<=1,'组合输入'!$D10*(1+'组合输入'!$E10),'组合输入'!$D10*'组合输入'!$E10+IF('参数'!$B$5+INDEX('利差假设'!$B$2:$B$9,MATCH(I$1,'利差假设'!$A$2:$A$9,0))=0,'组合输入'!$D10+'组合输入'!$D10*'组合输入'!$E10*('组合输入'!$F10-1),'组合输入'!$D10*'组合输入'!$E10*(1-(1+'参数'!$B$5+INDEX('利差假设'!$B$2:$B$9,MATCH(I$1,'利差假设'!$A$2:$A$9,0)))^-('组合输入'!$F10-1))/('参数'!$B$5+INDEX('利差假设'!$B$2:$B$9,MATCH(I$1,'利差假设'!$A$2:$A$9,0)))+'组合输入'!$D10*(1+'参数'!$B$5+INDEX('利差假设'!$B$2:$B$9,MATCH(I$1,'利差假设'!$A$2:$A$9,0)))^-('组合输入'!$F10-1))))) | J10: =IF($C10="","",IF(J$1="D",'组合输入'!$D10*'组合输入'!$G10,IF('组合输入'!$F10<=1,'组合输入'!$D10*(1+'组合输入'!$E10),'组合输入'!$D10*'组合输入'!$E10+IF('参数'!$B$5+INDEX('利差假设'!$B$2:$B$9,MATCH(J$1,'利差假设'!$A$2:$A$9,0))=0,'组合输入'!$D10+'组合输入'!$D10*'组合输入'!$E10*('组合输入'!$F10-1),'组合输入'!$D10*'组合输入'!$E10*(1-(1+'参数'!$B$5+INDEX('利差假设'!$B$2:$B$9,MATCH(J$1,'利差假设'!$A$2:$A$9,0)))^-('组合输入'!$F10-1))/('参数'!$B$5+INDEX('利差假设'!$B$2:$B$9,MATCH(J$1,'利差假设'!$A$2:$A$9,0)))+'组合输入'!$D10*(1+'参数'!$B$5+INDEX('利差假设'!$B$2:$B$9,MATCH(J$1,'利差假设'!$A$2:$A$9,0)))^-('组合输入'!$F10-1))))) | K10: =IF($C10="","",IF(K$1="D",'组合输入'!$D10*'组合输入'!$G10,IF('组合输入'!$F10<=1,'组合输入'!$D10*(1+'组合输入'!$E10),'组合输入'!$D10*'组合输入'!$E10+IF('参数'!$B$5+INDEX('利差假设'!$B$2:$B$9,MATCH(K$1,'利差假设'!$A$2:$A$9,0))=0,'组合输入'!$D10+'组合输入'!$D10*'组合输入'!$E10*('组合输入'!$F10-1),'组合输入'!$D10*'组合输入'!$E10*(1-(1+'参数'!$B$5+INDEX('利差假设'!$B$2:$B$9,MATCH(K$1,'利差假设'!$A$2:$A$9,0)))^-('组合输入'!$F10-1))/('参数'!$B$5+INDEX('利差假设'!$B$2:$B$9,MATCH(K$1,'利差假设'!$A$2:$A$9,0)))+'组合输入'!$D10*(1+'参数'!$B$5+INDEX('利差假设'!$B$2:$B$9,MATCH(K$1,'利差假设'!$A$2:$A$9,0)))^-('组合输入'!$F10-1))))) | L10: =IF($C10="","",SUMPRODUCT(INDEX('评级迁移'!$B$2:$I$9,MATCH($C10,'评级迁移'!$A$2:$A$9,0),0),$D10:$K10)) | M10: =IF($C10="","",SQRT(SUMPRODUCT(INDEX('评级迁移'!$B$2:$I$9,MATCH($C10,'评级迁移'!$A$2:$A$9,0),0),($D10:$K10-$L10)*($D10:$K10-$L10)))) | N10: =IF($C10="","",'组合输入'!$J10-$L10) | O10: =IF($C10="","",'组合输入'!$J10-MIN($D10:$K10))
A11: ='组合输入'!A11 | B11: ='组合输入'!B11 | C11: ='组合输入'!C11 | D11: =IF($C11="","",IF(D$1="D",'组合输入'!$D11*'组合输入'!$G11,IF('组合输入'!$F11<=1,'组合输入'!$D11*(1+'组合输入'!$E11),'组合输入'!$D11*'组合输入'!$E11+IF('参数'!$B$5+INDEX('利差假设'!$B$2:$B$9,MATCH(D$1,'利差假设'!$A$2:$A$9,0))=0,'组合输入'!$D11+'组合输入'!$D11*'组合输入'!$E11*('组合输入'!$F11-1),'组合输入'!$D11*'组合输入'!$E11*(1-(1+'参数'!$B$5+INDEX('利差假设'!$B$2:$B$9,MATCH(D$1,'利差假设'!$A$2:$A$9,0)))^-('组合输入'!$F11-1))/('参数'!$B$5+INDEX('利差假设'!$B$2:$B$9,MATCH(D$1,'利差假设'!$A$2:$A$9,0)))+'组合输入'!$D11*(1+'参数'!$B$5+INDEX('利差假设'!$B$2:$B$9,MATCH(D$1,'利差假设'!$A$2:$A$9,0)))^-('组合输入'!$F11-1))))) | E11: =IF($C11="","",IF(E$1="D",'组合输入'!$D11*'组合输入'!$G11,IF('组合输入'!$F11<=1,'组合输入'!$D11*(1+'组合输入'!$E11),'组合输入'!$D11*'组合输入'!$E11+IF('参数'!$B$5+INDEX('利差假设'!$B$2:$B$9,MATCH(E$1,'利差假设'!$A$2:$A$9,0))=0,'组合输入'!$D11+'组合输入'!$D11*'组合输入'!$E11*('组合输入'!$F11-1),'组合输入'!$D11*'组合输入'!$E11*(1-(1+'参数'!$B$5+INDEX('利差假设'!$B$2:$B$9,MATCH(E$1,'利差假设'!$A$2:$A$9,0)))^-('组合输入'!$F11-1))/('参数'!$B$5+INDEX('利差假设'!$B$2:$B$9,MATCH(E$1,'利差假设'!$A$2:$A$9,0)))+'组合输入'!$D11*(1+'参数'!$B$5+INDEX('利差假设'!$B$2:$B$9,MATCH(E$1,'利差假设'!$A$2:$A$9,0)))^-('组合输入'!$F11-1))))) | F11: =IF($C11="","",IF(F$1="D",'组合输入'!$D11*'组合输入'!$G11,IF('组合输入'!$F11<=1,'组合输入'!$D11*(1+'组合输入'!$E11),'组合输入'!$D11*'组合输入'!$E11+IF('参数'!$B$5+INDEX('利差假设'!$B$2:$B$9,MATCH(F$1,'利差假设'!$A$2:$A$9,0))=0,'组合输入'!$D11+'组合输入'!$D11*'组合输入'!$E11*('组合输入'!$F11-1),'组合输入'!$D11*'组合输入'!$E11*(1-(1+'参数'!$B$5+INDEX('利差假设'!$B$2:$B$9,MATCH(F$1,'利差假设'!$A$2:$A$9,0)))^-('组合输入'!$F11-1))/('参数'!$B$5+INDEX('利差假设'!$B$2:$B$9,MATCH(F$1,'利差假设'!$A$2:$A$9,0)))+'组合输入'!$D11*(1+'参数'!$B$5+INDEX('利差假设'!$B$2:$B$9,MATCH(F$1,'利差假设'!$A$2:$A$9,0)))^-('组合输入'!$F11-1))))) | G11: =IF($C11="","",IF(G$1="D",'组合输入'!$D11*'组合输入'!$G11,IF('组合输入'!$F11<=1,'组合输入'!$D11*(1+'组合输入'!$E11),'组合输入'!$D11*'组合输入'!$E11+IF('参数'!$B$5+INDEX('利差假设'!$B$2:$B$9,MATCH(G$1,'利差假设'!$A$2:$A$9,0))=0,'组合输入'!$D11+'组合输入'!$D11*'组合输入'!$E11*('组合输入'!$F11-1),'组合输入'!$D11*'组合输入'!$E11*(1-(1+'参数'!$B$5+INDEX('利差假设'!$B$2:$B$9,MATCH(G$1,'利差假设'!$A$2:$A$9,0)))^-('组合输入'!$F11-1))/('参数'!$B$5+INDEX('利差假设'!$B$2:$B$9,MATCH(G$1,'利差假设'!$A$2:$A$9,0)))+'组合输入'!$D11*(1+'参数'!$B$5+INDEX('利差假设'!$B$2:$B$9,MATCH(G$1,'利差假设'!$A$2:$A$9,0)))^-('组合输入'!$F11-1))))) | H11: =IF($C11="","",IF(H$1="D",'组合输入'!$D11*'组合输入'!$G11,IF('组合输入'!$F11<=1,'组合输入'!$D11*(1+'组合输入'!$E11),'组合输入'!$D11*'组合输入'!$E11+IF('参数'!$B$5+INDEX('利差假设'!$B$2:$B$9,MATCH(H$1,'利差假设'!$A$2:$A$9,0))=0,'组合输入'!$D11+'组合输入'!$D11*'组合输入'!$E11*('组合输入'!$F11-1),'组合输入'!$D11*'组合输入'!$E11*(1-(1+'参数'!$B$5+INDEX('利差假设'!$B$2:$B$9,MATCH(H$1,'利差假设'!$A$2:$A$9,0)))^-('组合输入'!$F11-1))/('参数'!$B$5+INDEX('利差假设'!$B$2:$B$9,MATCH(H$1,'利差假设'!$A$2:$A$9,0)))+'组合输入'!$D11*(1+'参数'!$B$5+INDEX('利差假设'!$B$2:$B$9,MATCH(H$1,'利差假设'!$A$2:$A$9,0)))^-('组合输入'!$F11-1))))) | I11: =IF($C11="","",IF(I$1="D",'组合输入'!$D11*'组合输入'!$G11,IF('组合输入'!$F11<=1,'组合输入'!$D11*(1+'组合输入'!$E11),'组合输入'!$D11*'组合输入'!$E11+IF('参数'!$B$5+INDEX('利差假设'!$B$2:$B$9,MATCH(I$1,'利差假设'!$A$2:$A$9,0))=0,'组合输入'!$D11+'组合输入'!$D11*'组合输入'!$E11*('组合输入'!$F11-1),'组合输入'!$D11*'组合输入'!$E11*(1-(1+'参数'!$B$5+INDEX('利差假设'!$B$2:$B$9,MATCH(I$1,'利差假设'!$A$2:$A$9,0)))^-('组合输入'!$F11-1))/('参数'!$B$5+INDEX('利差假设'!$B$2:$B$9,MATCH(I$1,'利差假设'!$A$2:$A$9,0)))+'组合输入'!$D11*(1+'参数'!$B$5+INDEX('利差假设'!$B$2:$B$9,MATCH(I$1,'利差假设'!$A$2:$A$9,0)))^-('组合输入'!$F11-1))))) | J11: =IF($C11="","",IF(J$1="D",'组合输入'!$D11*'组合输入'!$G11,IF('组合输入'!$F11<=1,'组合输入'!$D11*(1+'组合输入'!$E11),'组合输入'!$D11*'组合输入'!$E11+IF('参数'!$B$5+INDEX('利差假设'!$B$2:$B$9,MATCH(J$1,'利差假设'!$A$2:$A$9,0))=0,'组合输入'!$D11+'组合输入'!$D11*'组合输入'!$E11*('组合输入'!$F11-1),'组合输入'!$D11*'组合输入'!$E11*(1-(1+'参数'!$B$5+INDEX('利差假设'!$B$2:$B$9,MATCH(J$1,'利差假设'!$A$2:$A$9,0)))^-('组合输入'!$F11-1))/('参数'!$B$5+INDEX('利差假设'!$B$2:$B$9,MATCH(J$1,'利差假设'!$A$2:$A$9,0)))+'组合输入'!$D11*(1+'参数'!$B$5+INDEX('利差假设'!$B$2:$B$9,MATCH(J$1,'利差假设'!$A$2:$A$9,0)))^-('组合输入'!$F11-1))))) | K11: =IF($C11="","",IF(K$1="D",'组合输入'!$D11*'组合输入'!$G11,IF('组合输入'!$F11<=1,'组合输入'!$D11*(1+'组合输入'!$E11),'组合输入'!$D11*'组合输入'!$E11+IF('参数'!$B$5+INDEX('利差假设'!$B$2:$B$9,MATCH(K$1,'利差假设'!$A$2:$A$9,0))=0,'组合输入'!$D11+'组合输入'!$D11*'组合输入'!$E11*('组合输入'!$F11-1),'组合输入'!$D11*'组合输入'!$E11*(1-(1+'参数'!$B$5+INDEX('利差假设'!$B$2:$B$9,MATCH(K$1,'利差假设'!$A$2:$A$9,0)))^-('组合输入'!$F11-1))/('参数'!$B$5+INDEX('利差假设'!$B$2:$B$9,MATCH(K$1,'利差假设'!$A$2:$A$9,0)))+'组合输入'!$D11*(1+'参数'!$B$5+INDEX('利差假设'!$B$2:$B$9,MATCH(K$1,'利差假设'!$A$2:$A$9,0)))^-('组合输入'!$F11-1))))) | L11: =IF($C11="","",SUMPRODUCT(INDEX('评级迁移'!$B$2:$I$9,MATCH($C11,'评级迁移'!$A$2:$A$9,0),0),$D11:$K11)) | M11: =IF($C11="","",SQRT(SUMPRODUCT(INDEX('评级迁移'!$B$2:$I$9,MATCH($C11,'评级迁移'!$A$2:$A$9,0),0),($D11:$K11-$L11)*($D11:$K11-$L11)))) | N11: =IF($C11="","",'组合输入'!$J11-$L11) | O11: =IF($C11="","",'组合输入'!$J11-MIN($D11:$K11))

Sheet 模拟
A1: 场景 | B1: 系统因子 | C1: 债项1_个体因子 | D1: 债项1_资产回报 | E1: 债项1_百分位 | F1: 债项1_迁移评级 | G1: 债项1_价值 | H1: 债项2_个体因子 | I1: 债项2_资产回报 | J1: 债项2_百分位 | K1: 债项2_迁移评级 | L1: 债项2_价值 | M1: 债项3_个体因子 | N1: 债项3_资产回报 | O1: 债项3_百分位 | P1: 债项3_迁移评级 | Q1: 债项3_价值 | R1: 债项4_个体因子 | S1: 债项4_资产回报 | T1: 债项4_百分位 | U1: 债项4_迁移评级 | V1: 债项4_价值 | W1: 债项5_个体因子 | X1: 债项5_资产回报 | Y1: 债项5_百分位 | Z1: 债项5_迁移评级 | AA1: 债项5_价值 | AB1: 债项6_个体因子 | AC1: 债项6_资产回报 | AD1: 债项6_百分位 | AE1: 债项6_迁移评级 | AF1: 债项6_价值 | AG1: 债项7_个体因子 | AH1: 债项7_资产回报 | AI1: 债项7_百分位 | AJ1: 债项7_迁移评级 | AK1: 债项7_价值 | AL1: 债项8_个体因子 | AM1: 债项8_资产回报 | AN1: 债项8_百分位 | AO1: 债项8_迁移评级 | AP1: 债项8_价值 | AQ1: 债项9_个体因子 | AR1: 债项9_资产回报 | AS1: 债项9_百分位 | AT1: 债项9_迁移评级 | AU1: 债项9_价值 | AV1: 债项10_个体因子 | AW1: 债项10_资产回报 | AX1: 债项10_百分位 | AY1: 债项10_迁移评级 | AZ1: 债项10_价值 | BA1: 组合价值 | BB1: 组合损失
